Workbook

Sheet Summary
A1: INVESTMENT SUMMARY
A2: =Inputs!C5&" | "&Inputs!C6&" | "&Inputs!C7&", "&Inputs!C8 -> | | ,
A4: DEAL OVERVIEW | E4: WATERFALL RETURN
B5: Purchase Price | C5: =Inputs!C10 | E5: LP (Capital Partner)
B6: Number of Units | C6: =Inputs!C9 | E6: IRR | F6: ='Equity Waterfall'!N62 -> -
B7: Total Equity Required | C7: =Inputs!C87 -> -345000 | E7: Equity Multiple | F7: ='Equity Waterfall'!N63 -> 0
B8: Total Debt (Acquisition) | C8: =Inputs!C43+Inputs!C52 -> 350000 | E8: Total Distributions | F8: ='Equity Waterfall'!N64 -> 0
B9: LTV | C9: =(Inputs!C43+Inputs!C52)/Inputs!C10 -> #DIV/0! | E9: Equity Invested | F9: =Inputs!C88 -> 85000
B10: Price Per Unit | C10: =Inputs!C10/Inputs!C9 -> #DIV/0! | E10: GP (Manager)
B11: Year 1 Cap Rate | C11: ='Annual CF'!C17/Inputs!C10 -> #DIV/0! | E11: IRR | F11: ='Equity Waterfall'!N67 -> -
B12: Hold Period | C12: =Inputs!C15 | E12: Equity Multiple | F12: ='Equity Waterfall'!N68 -> 0
B13: Refi Year | C13: =Inputs!C16 | E13: Total Distributions | F13: ='Equity Waterfall'!N69 -> 0
B14: Exit Cap Rate | C14: =Inputs!C96 -> 0.09 | E14: Equity Invested | F14: =Inputs!C89 -> -430000
A16: SOURCES & USES | E16: KEY PERFORMANCE METRICS
B17: Purchase Price | C17: =Inputs!C10 | E17: Year 1 NOI | F17: ='Annual CF'!C17 -> 0
B18: Closing Costs | C18: =Inputs!C85 -> 0 | E18: Year 1 DSCR | F18: ='Annual CF'!C72 -> -
B19: Due Diligence | C19: =Inputs!C10*Inputs!C12 -> 0 | E19: Year 1 Cash-on-Cash | F19: =IF(Inputs!C87=0,0,'Annual CF'!C62/Inputs!C87) -> 1.0144928
B20: Loan Origination | C20: =Inputs!C10*Inputs!C13 -> 0 | E20: Year 1 Cap Rate | F20: ='Annual CF'!C17/Inputs!C10 -> #DIV/0!
B21: Immediate Repairs | C21: =Inputs!C86 -> 5000 | E21: 10-Year Total NOI | F21: =SUM('Annual CF'!C17:L17) -> 0
B22: TOTAL USES | C22: =Inputs!C81 -> 5000 | E22: 10-Year Total CFAD | F22: =SUM('Annual CF'!C62:L62) -> -350000
B23: Funded By | E23: Exit Selling Price | F23: =Inputs!C101 -> 0
B24: Seller Finance | C24: =Inputs!C43 -> 0 | E24: Net Sale Proceeds | F24: =Inputs!C103 -> 0
B25: Bank Loan | C25: =Inputs!C52 -> 350000 | E25: Feasibility Checks
B26: Equity | C26: =Inputs!C87 -> -345000 | E26: Year 1 DSCR ≥ 1.25x? | F26: =IF('Annual CF'!C72>=1.25,"✓ PASS","✗ FAIL") -> ✓ PASS
E27: Year 1 CF > $0? | F27: =IF('Annual CF'!C62>0,"✓ PASS","✗ FAIL") -> ✗ FAIL
A29: 10-YEAR ANNUAL SNAPSHOT
B30: Metric | C30: Year 1 | D30: Year 2 | E30: Year 3 | F30: Year 4 | G30: Year 5 | H30: Year 6 | I30: Year 7 | J30: Year 8 | K30: Year 9 | L30: Year 10
B31: NOI | C31: ='Annual CF'!C17 -> 0 | D31: ='Annual CF'!D17 -> 0 | E31: ='Annual CF'!E17 -> 0 | F31: ='Annual CF'!F17 -> 0 | G31: ='Annual CF'!G17 -> 0 | H31: ='Annual CF'!H17 -> 0 | I31: ='Annual CF'!I17 -> 0 | J31: ='Annual CF'!J17 -> 0 | ... L31: ='Annual CF'!L17 -> 0
B32: CF Before Debt | C32: ='Annual CF'!C28 -> -5000 | D32: ='Annual CF'!D28 -> 0 | E32: ='Annual CF'!E28 -> 0 | F32: ='Annual CF'!F28 -> 0 | G32: ='Annual CF'!G28 -> 0 | H32: ='Annual CF'!H28 -> 0 | I32: ='Annual CF'!I28 -> 0 | J32: ='Annual CF'!J28 -> 0 | ... L32: ='Annual CF'!L28 -> 0
B33: CF After Debt | C33: ='Annual CF'!C62 -> -350000 | D33: ='Annual CF'!D62 -> 0 | E33: ='Annual CF'!E62 -> 0 | F33: ='Annual CF'!F62 -> 0 | G33: ='Annual CF'!G62 -> 0 | H33: ='Annual CF'!H62 -> 0 | I33: ='Annual CF'!I62 -> 0 | J33: ='Annual CF'!J62 -> 0 | ... L33: ='Annual CF'!L62 -> 0
B34: DSCR | C34: ='Annual CF'!C72 -> - | D34: ='Annual CF'!D72 -> - | E34: ='Annual CF'!E72 -> - | F34: ='Annual CF'!F72 -> - | G34: ='Annual CF'!G72 -> - | H34: ='Annual CF'!H72 -> - | I34: ='Annual CF'!I72 -> - | J34: ='Annual CF'!J72 -> - | ... L34: ='Annual CF'!L72 -> -
B35: LP Distributions | C35: ='Annual CF'!C67 -> 0 | D35: ='Annual CF'!D67 -> 0 | E35: ='Annual CF'!E67 -> 0 | F35: ='Annual CF'!F67 -> 0 | G35: ='Annual CF'!G67 -> 0 | H35: ='Annual CF'!H67 -> 0 | I35: ='Annual CF'!I67 -> 0 | J35: ='Annual CF'!J67 -> 0 | ... L35: ='Annual CF'!L67 -> 0
B36: GP Distributions | C36: ='Annual CF'!C69 -> 0 | D36: ='Annual CF'!D69 -> 0 | E36: ='Annual CF'!E69 -> 0 | F36: ='Annual CF'!F69 -> 0 | G36: ='Annual CF'!G69 -> 0 | H36: ='Annual CF'!H69 -> 0 | I36: ='Annual CF'!I69 -> 0 | J36: ='Annual CF'!J69 -> 0 | ... L36: ='Annual CF'!L69 -> 0
B37: Cumulative CF | C37: ='Annual CF'!C63 -> -350000 | D37: ='Annual CF'!D63 -> -350000 | E37: ='Annual CF'!E63 -> -350000 | F37: ='Annual CF'!F63 -> -350000 | G37: ='Annual CF'!G63 -> -350000 | H37: ='Annual CF'!H63 -> -350000 | I37: ='Annual CF'!I63 -> -350000 | J37: ='Annual CF'!J63 -> -350000 | ... L37: ='Annual CF'!L63 -> -350000
A39: PROJECT-LEVEL RETURNS | E39: FINANCING SUMMARY
B40: Project IRR | C40: ='Equity Waterfall'!N72 -> - | E40: Seller Finance | F40: =Inputs!C43 -> 0
B41: Project Equity Multiple | C41: ='Equity Waterfall'!N73 -> 0 | E41: Rate / Amort / Balloon | F41: =TEXT(Inputs!C44,"0.0%")&" / "&Inputs!C45&"yr / Yr "&Inputs!C46 -> 5.0% / 25yr / Yr 5
B42: Total Distributable Cash | C42: ='Equity Waterfall'!N53 -> 0 | E42: Bank Loan | F42: =Inputs!C52 -> 350000
B43: Total LP Distributions | C43: ='Equity Waterfall'!N51 -> 0 | E43: Rate / Amort / Balloon | F43: =TEXT(Inputs!C53,"0.0%")&" / "&Inputs!C54&"yr / Yr "&Inputs!C55 -> 5.0% / 25yr / Yr 5
B44: Total GP Distributions | C44: ='Equity Waterfall'!N52 -> 0 | E44: Refi Loan (Year 6) | F44: =Inputs!C67 -> 0
...

Sheet Inputs
A1: COMMERCIAL REAL ESTATE UNDERWRITING MODEL
A2: INPUT ASSUMPTIONS | All blue cells are inputs
A4: SECTION 1 · PROPERTY INFORMATION
B5: Property Name
B6: Property Type
B7: Address
B8: City / State
B9: Number of Units
B10: Purchase Price | D10: Amount ($)
B11: Down Payment (%) | D11: =C10*C11 -> 0
B12: Due Diligence Costs (%) | C12: =IF(C10=0,0,D12/C10) -> 0
B13: Loan Origination Costs (%) | D13: =C10*C13 -> 0
B14: Purchase Date
B15: End Year
B16: Refi Year
A18: SECTION 2 · REVENUE ASSUMPTIONS | C18: T12 | D18: % Change | E18: Proforma Y-1
B19: Enter monthly T12 averages; model annualizes and projects forward
B20: Gross Potential Rent | D20: 0.1 | E20: =C20*(1+D20) -> 0
B21: Vacancy (%) | E21: =C21
B22: Credit Loss (%) | E22: =C22
B23: SUM Income | C23: =IncomeExpenses!C47 -> 0 | D23: 0.05 | E23: =C23*(1+D23) -> 0
B24: Annual Revenue Growth Rate | C24: 0.05
B25: Revenue Start Month | C25: 1
A27: SECTION 3 · EXPENSE ASSUMPTIONS | C27: T12 | D27: % Change | E27: Proforma Y-1
B28: Property Management Fee (%EGI) | E28: =C28
B29: SUM Expenses | C29: =IncomeExpenses!C90 -> 0
B30: Annual Expense Growth Rate | C30: 0.03
B31: Expense Start Month | C31: 1
A33: SECTION 4 · CAPITAL EXPENDITURES | C33: Amount | D33: Month
B34: CapEx Item 1 | D34: 1
B35: CapEx Item 2 | D35: 4
B36: CapEx Item 3 | D36: 7
B37: CapEx Item 4 | D37: 9
B38: CapEx Item 5 | D38: 11
B39: CapEx Item 6 | D39: 13
A41: SECTION 5 · FUNDING & DEBT ASSUMPTIONS
B42: Acquisition - Seller Finance
B43: Seller Finance Amount | C43: =D81 -> 0
B44: Seller Finance Interest Rate | C44: 0.05
B45: Seller Finance Amortization (Yrs) | C45: 25
...

Sheet IncomeExpenses
A1: COMMERCIAL REAL ESTATE UNDERWRITING MODEL
A2: INPUT ASSUMPTIONS | All blue cells are inputs
A5: SECTION 1 · REVENUE ASSUMPTIONS | C5: T12 | D5: % Change | E5: Proforma Y-1
B6: Enter monthly T12 averages; model annualizes and projects forward
B7: Late Fees | D7: 0.05 | E7: =C7*(1+D7) -> 0
B8: Lot Rent | D8: 0.05 | E8: =C8*(1+D8) -> 0
B9: Down Payment Income | D9: 0.05 | E9: =C9*(1+D9) -> 0
B10: Waste Removal Utility Income | D10: 0.05 | E10: =C10*(1+D10) -> 0
B11: Home Sales | D11: 0.05 | E11: =C11*(1+D11) -> 0
B12: Eviction Fees Collected | D12: 0.05 | E12: =C12*(1+D12) -> 0
D13: 0.05 | E13: =C13*(1+D13) -> 0
D14: 0.05 | E14: =C14*(1+D14) -> 0
D15: 0.05 | E15: =C15*(1+D15) -> 0
D16: 0.05 | E16: =C16*(1+D16) -> 0
D17: 0.05 | E17: =C17*(1+D17) -> 0
D18: 0.05 | E18: =C18*(1+D18) -> 0
D19: 0.05 | E19: =C19*(1+D19) -> 0
D20: 0.05 | E20: =C20*(1+D20) -> 0
D21: 0.05 | E21: =C21*(1+D21) -> 0
D22: 0.05 | E22: =C22*(1+D22) -> 0
D23: 0.05 | E23: =C23*(1+D23) -> 0
D24: 0.05 | E24: =C24*(1+D24) -> 0
... D46: 0.05 | E46: =C46*(1+D46) -> 0
C47: =SUM(C7:C46) -> 0 | E47: =SUM(E7:E46) -> 0
A49: SECTION 2 · EXPENSE ASSUMPTIONS | C49: T12 | D49: % Change | E49: Proforma Y-1
B50: Property Tax | D50: 0.04 | E50: =C50*(1+D50) -> 0
B51: Insurance | D51: 0.04 | E51: =C51*(1+D51) -> 0
B52: Repairs | D52: 0.04 | E52: =C52*(1+D52) -> 0
B53: Utilities | D53: 0.04 | E53: =C53*(1+D53) -> 0
B54: Capital Expenditures | D54: 0.04 | E54: =C54*(1+D54) -> 0
B55: Landscape | D55: 0.04 | E55: =C55*(1+D55) -> 0
B56: Legal Fees | D56: 0.04 | E56: =C56*(1+D56) -> 0
B57: Sheriff Eviction Fee | D57: 0.04 | E57: =C57*(1+D57) -> 0
B58: CAM - Insurance | D58: 0.04 | E58: =C58*(1+D58) -> 0
B59: Other CAM Expenses | D59: 0.04 | E59: =C59*(1+D59) -> 0
B60: Software | D60: 0.04 | E60: =C60*(1+D60) -> 0
B61: Bad Debt | D61: 0.04 | E61: =C61*(1+D61) -> 0
... B69: Remove mobile home | D69: 0.02 | E69: =C69*(1+D69) -> 0
D70: 0.02 | E70: =C70*(1+D70) -> 0
D71: 0.02 | E71: =C71*(1+D71) -> 0
...

Sheet Notes
A1: NOTES FOR PEDRO – What Data Does the Client Give Us?
A3: Hey Pedro! This document explains what information we need from the client so we can plug it into our model.
A4: The "Inputs" sheet is where ALL the client data goes. Think of it as the control panel — everything we type there drives the entire model.
A5: Blue cells = things we type in (client data or our assumptions). Black cells = the model calculates automatically. Green cells = pulled from other sheets.
A7: Below is a section-by-section breakdown of what the client provides and where it goes.
A9: ═══════════════════════════════════════════════════════════════════
A10: SECTION 1 · PROPERTY INFORMATION (Inputs sheet, rows 5–16)
A11: ═══════════════════════════════════════════════════════════════════
A13: This is basic info about the property the client wants to buy. Ask the client for:
A15: • Property Name (cell C5) — What is the property called? Example: "High Land Park"
A16: • Property Type (cell C6) — What kind of property? Example: "RV Park", "Apartment", "Retail"
A17: • Address (cell C7) — Street address of the property
... A148: 7. Waterfall terms — preferred return %, catch-up terms, profit split percentages for each tier

Sheet Monthly CF
A1: MONTHLY CASHFLOW MODEL
A2: All values driven by Inputs sheet | Blue = Input | Green = Linked | Black = Formula
B3: Month No. | C3: 1 | D3: 2 | E3: 3 | F3: 4 | G3: 5 | H3: 6 | I3: 7 | J3: 8 | K3: 9 | L3: 10 | M3: 11 | N3: 12 | O3: 13 | P3: 14 | Q3: 15 | R3: 16 | S3: 17 | T3: 18 | U3: 19 | V3: 20 | W3: 21 | X3: 22 | Y3: 23 | Z3: 24 | AA3: 25 | AB3: 26 | AC3: 27 | AD3: 28 | AE3: 29 | AF3: 30 | AG3: 31 | AH3: 32 | AI3: 33 | AJ3: 34 | AK3: 35 | AL3: 36 | AM3: 37 | AN3: 38 | AO3: 39 | AP3: 40 | AQ3: 41 | AR3: 42 | AS3: 43 | AT3: 44 | AU3: 45 | AV3: 46 | AW3: 47 | AX3: 48 | AY3: 49 | AZ3: 50 | BA3: 51 | BB3: 52 | BC3: 53 | BD3: 54 | BE3: 55 | BF3: 56 | BG3: 57 | BH3: 58 | BI3: 59 | BJ3: 60 | BK3: 61 | BL3: 62 | BM3: 63 | BN3: 64 | BO3: 65 | BP3: 66 | BQ3: 67 | BR3: 68 | BS3: 69 | BT3: 70 | BU3: 71 | BV3: 72 | BW3: 73 | BX3: 74 | BY3: 75 | BZ3: 76 | CA3: 77 | CB3: 78 | CC3: 79 | CD3: 80 | CE3: 81 | CF3: 82 | CG3: 83 | CH3: 84 | CI3: 85 | CJ3: 86 | CK3: 87 | CL3: 88 | CM3: 89 | CN3: 90 | CO3: 91 | CP3: 92 | CQ3: 93 | CR3: 94 | CS3: 95 | CT3: 96 | CU3: 97 | CV3: 98 | CW3: 99 | CX3: 100 | CY3: 101 | CZ3: 102 | DA3: 103 | DB3: 104 | DC3: 105 | DD3: 106 | DE3: 107 | DF3: 108 | DG3: 109 | DH3: 110 | DI3: 111 | DJ3: 112 | DK3: 113 | DL3: 114 | DM3: 115 | DN3: 116 | DO3: 117 | DP3: 118 | DQ3: 119 | DR3: 120
B4: Quarter No. | C4: 1 | D4: 1 | E4: 1 | F4: 2 | G4: 2 | H4: 2 | I4: 3 | J4: 3 | K4: 3 | L4: 4 | M4: 4 | N4: 4 | O4: 5 | P4: 5 | Q4: 5 | R4: 6 | S4: 6 | T4: 6 | U4: 7 | V4: 7 | W4: 7 | X4: 8 | Y4: 8 | Z4: 8 | AA4: 9 | AB4: 9 | AC4: 9 | AD4: 10 | AE4: 10 | AF4: 10 | AG4: 11 | AH4: 11 | AI4: 11 | AJ4: 12 | AK4: 12 | AL4: 12 | AM4: 13 | AN4: 13 | AO4: 13 | AP4: 14 | AQ4: 14 | AR4: 14 | AS4: 15 | AT4: 15 | AU4: 15 | AV4: 16 | AW4: 16 | AX4: 16 | AY4: 17 | AZ4: 17 | BA4: 17 | BB4: 18 | BC4: 18 | BD4: 18 | BE4: 19 | BF4: 19 | BG4: 19 | BH4: 20 | BI4: 20 | BJ4: 20 | BK4: 21 | BL4: 21 | BM4: 21 | BN4: 22 | BO4: 22 | BP4: 22 | BQ4: 23 | BR4: 23 | BS4: 23 | BT4: 24 | BU4: 24 | BV4: 24 | BW4: 25 | BX4: 25 | BY4: 25 | BZ4: 26 | CA4: 26 | CB4: 26 | CC4: 27 | CD4: 27 | CE4: 27 | CF4: 28 | CG4: 28 | CH4: 28 | CI4: 29 | CJ4: 29 | CK4: 29 | CL4: 30 | CM4: 30 | CN4: 30 | CO4: 31 | CP4: 31 | CQ4: 31 | CR4: 32 | CS4: 32 | CT4: 32 | CU4: 33 | CV4: 33 | CW4: 33 | CX4: 34 | CY4: 34 | CZ4: 34 | DA4: 35 | DB4: 35 | DC4: 35 | DD4: 36 | DE4: 36 | DF4: 36 | DG4: 37 | DH4: 37 | DI4: 37 | DJ4: 38 | DK4: 38 | DL4: 38 | DM4: 39 | DN4: 39 | DO4: 39 | DP4: 40 | DQ4: 40 | DR4: 40
B5: Year No. | C5: 1 | D5: 1 | E5: 1 | F5: 1 | G5: 1 | H5: 1 | I5: 1 | J5: 1 | K5: 1 | L5: 1 | M5: 1 | N5: 1 | O5: 2 | P5: 2 | Q5: 2 | R5: 2 | S5: 2 | T5: 2 | U5: 2 | V5: 2 | W5: 2 | X5: 2 | Y5: 2 | Z5: 2 | AA5: 3 | AB5: 3 | AC5: 3 | AD5: 3 | AE5: 3 | AF5: 3 | AG5: 3 | AH5: 3 | AI5: 3 | AJ5: 3 | AK5: 3 | AL5: 3 | AM5: 4 | AN5: 4 | AO5: 4 | AP5: 4 | AQ5: 4 | AR5: 4 | AS5: 4 | AT5: 4 | AU5: 4 | AV5: 4 | AW5: 4 | AX5: 4 | AY5: 5 | AZ5: 5 | BA5: 5 | BB5: 5 | BC5: 5 | BD5: 5 | BE5: 5 | BF5: 5 | BG5: 5 | BH5: 5 | BI5: 5 | BJ5: 5 | BK5: 6 | BL5: 6 | BM5: 6 | BN5: 6 | BO5: 6 | BP5: 6 | BQ5: 6 | BR5: 6 | BS5: 6 | BT5: 6 | BU5: 6 | BV5: 6 | BW5: 7 | BX5: 7 | BY5: 7 | BZ5: 7 | CA5: 7 | CB5: 7 | CC5: 7 | CD5: 7 | CE5: 7 | CF5: 7 | CG5: 7 | CH5: 7 | CI5: 8 | CJ5: 8 | CK5: 8 | CL5: 8 | CM5: 8 | CN5: 8 | CO5: 8 | CP5: 8 | CQ5: 8 | CR5: 8 | CS5: 8 | CT5: 8 | CU5: 9 | CV5: 9 | CW5: 9 | CX5: 9 | CY5: 9 | CZ5: 9 | DA5: 9 | DB5: 9 | DC5: 9 | DD5: 9 | DE5: 9 | DF5: 9 | DG5: 10 | DH5: 10 | DI5: 10 | DJ5: 10 | DK5: 10 | DL5: 10 | DM5: 10 | DN5: 10 | DO5: 10 | DP5: 10 | DQ5: 10 | DR5: 10
C6: 45658 | D6: 45689 | E6: 45717 | F6: 45748 | G6: 45778 | H6: 45809 | I6: 45839 | J6: 45870 | K6: 45901 | L6: 45931 | M6: 45962 | N6: 45992 | O6: 46023 | P6: 46054 | Q6: 46082 | R6: 46113 | S6: 46143 | T6: 46174 | U6: 46204 | V6: 46235 | W6: 46266 | X6: 46296 | Y6: 46327 | Z6: 46357 | AA6: 46388 | AB6: 46419 | AC6: 46447 | AD6: 46478 | AE6: 46508 | AF6: 46539 | AG6: 46569 | AH6: 46600 | AI6: 46631 | AJ6: 46661 | AK6: 46692 | AL6: 46722 | AM6: 46753 | AN6: 46784 | AO6: 46813 | AP6: 46844 | AQ6: 46874 | AR6: 46905 | AS6: 46935 | AT6: 46966 | AU6: 46997 | AV6: 47027 | AW6: 47058 | AX6: 47088 | AY6: 47119 | AZ6: 47150 | BA6: 47178 | BB6: 47209 | BC6: 47239 | BD6: 47270 | BE6: 47300 | BF6: 47331 | BG6: 47362 | BH6: 47392 | BI6: 47423 | BJ6: 47453 | BK6: 47484 | BL6: 47515 | BM6: 47543 | BN6: 47574 | BO6: 47604 | BP6: 47635 | BQ6: 47665 | BR6: 47696 | BS6: 47727 | BT6: 47757 | BU6: 47788 | BV6: 47818 | BW6: 47849 | BX6: 47880 | BY6: 47908 | BZ6: 47939 | CA6: 47969 | CB6: 48000 | CC6: 48030 | CD6: 48061 | CE6: 48092 | CF6: 48122 | CG6: 48153 | CH6: 48183 | CI6: 48214 | CJ6: 48245 | CK6: 48274 | CL6: 48305 | CM6: 48335 | CN6: 48366 | CO6: 48396 | CP6: 48427 | CQ6: 48458 | CR6: 48488 | CS6: 48519 | CT6: 48549 | CU6: 48580 | CV6: 48611 | CW6: 48639 | CX6: 48670 | CY6: 48700 | CZ6: 48731 | DA6: 48761 | DB6: 48792 | DC6: 48823 | DD6: 48853 | DE6: 48884 | DF6: 48914 | DG6: 48945 | DH6: 48976 | DI6: 49004 | DJ6: 49035 | DK6: 49065 | DL6: 49096 | DM6: 49126 | DN6: 49157 | DO6: 49188 | DP6: 49218 | DQ6: 49249 | DR6: 49279
B7: REVENUE
B8: Gross Potential Rent | C8: {=IF(AND(C$3>=INDEX(Inputs!$C:$C,MATCH("*Revenue Start Month*",Inputs!$B:$B,0)),C$3<=INDEX(Inputs!$C:$C,MATCH("End Year",Inputs!$B:$B,0))*12),INDEX(Inputs!$E:$E,MATCH("*Gross Potential Rent*",Inputs!$B:$B,0))/12*(1+INDEX(Inputs!$C:$C,MATCH("*Annual Revenue Growth Rate*",Inputs!$B:$B,0)))^(C$5-1),0)} -> 0 | D8: {=IF(AND(D$3>=INDEX(Inputs!$C:$C,MATCH("*Revenue Start Month*",Inputs!$B:$B,0)),D$3<=INDEX(Inputs!$C:$C,MATCH("End Year",Inputs!$B:$B,0))*12),INDEX(Inputs!$E:$E,MATCH("*Gross Potential Rent*",Inputs!$B:$B,0))/12*(1+INDEX(Inputs!$C:$C,MATCH("*Annual Revenue Growth Rate*",Inputs!$B:$B,0)))^(D$5-1),0)} -> 0 | E8: {=IF(AND(E$3>=INDEX(Inputs!$C:$C,MATCH("*Revenue Start Month*",Inputs!$B:$B,0)),E$3<=INDEX(Inputs!$C:$C,MATCH("End Year",Inputs!$B:$B,0))*12),INDEX(Inputs!$E:$E,MATCH("*Gross Potential Rent*",Inputs!$B:$B,0))/12*(1+INDEX(Inputs!$C:$C,MATCH("*Annual Revenue Growth Rate*",Inputs!$B:$B,0)))^(E$5-1),0)} -> 0 | F8: {=IF(AND(F$3>=INDEX(Inputs!$C:$C,MATCH("*Revenue Start Month*",Inputs!$B:$B,0)),F$3<=INDEX(Inputs!$C:$C,MATCH("End Year",Inputs!$B:$B,0))*12),INDEX(Inputs!$E:$E,MATCH("*Gross Potential Rent*",Inputs!$B:$B,0))/12*(1+INDEX(Inputs!$C:$C,MATCH("*Annual Revenue Growth Rate*",Inputs!$B:$B,0)))^(F$5-1),0)} -> 0 | G8: {=IF(AND(G$3>=INDEX(Inputs!$C:$C,MATCH("*Revenue Start Month*",Inputs!$B:$B,0)),G$3<=INDEX(Inputs!$C:$C,MATCH("End Year",Inputs!$B:$B,0))*12),INDEX(Inputs!$E:$E,MATCH("*Gross Potential Rent*",Inputs!$B:$B,0))/12*(1+INDEX(Inputs!$C:$C,MATCH("*Annual Revenue Growth Rate*",Inputs!$B:$B,0)))^(G$5-1),0)} -> 0 | H8: {=IF(AND(H$3>=INDEX(Inputs!$C:$C,MATCH("*Revenue Start Month*",Inputs!$B:$B,0)),H$3<=INDEX(Inputs!$C:$C,MATCH("End Year",Inputs!$B:$B,0))*12),INDEX(Inputs!$E:$E,MATCH("*Gross Potential Rent*",Inputs!$B:$B,0))/12*(1+INDEX(Inputs!$C:$C,MATCH("*Annual Revenue Growth Rate*",Inputs!$B:$B,0)))^(H$5-1),0)} -> 0 | I8: {=IF(AND(I$3>=INDEX(Inputs!$C:$C,MATCH("*Revenue Start Month*",Inputs!$B:$B,0)),I$3<=INDEX(Inputs!$C:$C,MATCH("End Year",Inputs!$B:$B,0))*12),INDEX(Inputs!$E:$E,MATCH("*Gross Potential Rent*",Inputs!$B:$B,0))/12*(1+INDEX(Inputs!$C:$C,MATCH("*Annual Revenue Growth Rate*",Inputs!$B:$B,0)))^(I$5-1),0)} -> 0 | J8: {=IF(AND(J$3>=INDEX(Inputs!$C:$C,MATCH("*Revenue Start Month*",Inputs!$B:$B,0)),J$3<=INDEX(Inputs!$C:$C,MATCH("End Year",Inputs!$B:$B,0))*12),INDEX(Inputs!$E:$E,MATCH("*Gross Potential Rent*",Inputs!$B:$B,0))/12*(1+INDEX(Inputs!$C:$C,MATCH("*Annual Revenue Growth Rate*",Inputs!$B:$B,0)))^(J$5-1),0)} -> 0 | ... DS8: {=IF(AND(DS$3>=INDEX(Inputs!$C:$C,MATCH("*Revenue Start Month*",Inputs!$B:$B,0)),DS$3<=INDEX(Inputs!$C:$C,MATCH("End Year",Inputs!$B:$B,0))*12),INDEX(Inputs!$E:$E,MATCH("*Gross Potential Rent*",Inputs!$B:$B,0))/12*(1+INDEX(Inputs!$C:$C,MATCH("*Annual Revenue Growth Rate*",Inputs!$B:$B,0)))^(DS$5-1),0)} -> 0
B9: Less: Vacancy | C9: {=IF(C$3<=INDEX(Inputs!$C:$C,MATCH("End Year",Inputs!$B:$B,0))*12,-C8*INDEX(Inputs!$E:$E,MATCH("*Vacancy*",Inputs!$B:$B,0)),0)} -> 0 | D9: {=IF(D$3<=INDEX(Inputs!$C:$C,MATCH("End Year",Inputs!$B:$B,0))*12,-D8*INDEX(Inputs!$E:$E,MATCH("*Vacancy*",Inputs!$B:$B,0)),0)} -> 0 | E9: {=IF(E$3<=INDEX(Inputs!$C:$C,MATCH("End Year",Inputs!$B:$B,0))*12,-E8*INDEX(Inputs!$E:$E,MATCH("*Vacancy*",Inputs!$B:$B,0)),0)} -> 0 | F9: {=IF(F$3<=INDEX(Inputs!$C:$C,MATCH("End Year",Inputs!$B:$B,0))*12,-F8*INDEX(Inputs!$E:$E,MATCH("*Vacancy*",Inputs!$B:$B,0)),0)} -> 0 | G9: {=IF(G$3<=INDEX(Inputs!$C:$C,MATCH("End Year",Inputs!$B:$B,0))*12,-G8*INDEX(Inputs!$E:$E,MATCH("*Vacancy*",Inputs!$B:$B,0)),0)} -> 0 | H9: {=IF(H$3<=INDEX(Inputs!$C:$C,MATCH("End Year",Inputs!$B:$B,0))*12,-H8*INDEX(Inputs!$E:$E,MATCH("*Vacancy*",Inputs!$B:$B,0)),0)} -> 0 | I9: {=IF(I$3<=INDEX(Inputs!$C:$C,MATCH("End Year",Inputs!$B:$B,0))*12,-I8*INDEX(Inputs!$E:$E,MATCH("*Vacancy*",Inputs!$B:$B,0)),0)} -> 0 | J9: {=IF(J$3<=INDEX(Inputs!$C:$C,MATCH("End Year",Inputs!$B:$B,0))*12,-J8*INDEX(Inputs!$E:$E,MATCH("*Vacancy*",Inputs!$B:$B,0)),0)} -> 0 | ... DS9: {=IF(DS$3<=INDEX(Inputs!$C:$C,MATCH("End Year",Inputs!$B:$B,0))*12,-DS8*INDEX(Inputs!$E:$E,MATCH("*Vacancy*",Inputs!$B:$B,0)),0)} -> 0
B10: Less: Credit Loss | C10: {=IF(C$3<=INDEX(Inputs!$C:$C,MATCH("End Year",Inputs!$B:$B,0))*12,-C8*INDEX(Inputs!$E:$E,MATCH("*Credit Loss*",Inputs!$B:$B,0)),0)} -> 0 | D10: {=IF(D$3<=INDEX(Inputs!$C:$C,MATCH("End Year",Inputs!$B:$B,0))*12,-D8*INDEX(Inputs!$E:$E,MATCH("*Credit Loss*",Inputs!$B:$B,0)),0)} -> 0 | E10: {=IF(E$3<=INDEX(Inputs!$C:$C,MATCH("End Year",Inputs!$B:$B,0))*12,-E8*INDEX(Inputs!$E:$E,MATCH("*Credit Loss*",Inputs!$B:$B,0)),0)} -> 0 | F10: {=IF(F$3<=INDEX(Inputs!$C:$C,MATCH("End Year",Inputs!$B:$B,0))*12,-F8*INDEX(Inputs!$E:$E,MATCH("*Credit Loss*",Inputs!$B:$B,0)),0)} -> 0 | G10: {=IF(G$3<=INDEX(Inputs!$C:$C,MATCH("End Year",Inputs!$B:$B,0))*12,-G8*INDEX(Inputs!$E:$E,MATCH("*Credit Loss*",Inputs!$B:$B,0)),0)} -> 0 | H10: {=IF(H$3<=INDEX(Inputs!$C:$C,MATCH("End Year",Inputs!$B:$B,0))*12,-H8*INDEX(Inputs!$E:$E,MATCH("*Credit Loss*",Inputs!$B:$B,0)),0)} -> 0 | I10: {=IF(I$3<=INDEX(Inputs!$C:$C,MATCH("End Year",Inputs!$B:$B,0))*12,-I8*INDEX(Inputs!$E:$E,MATCH("*Credit Loss*",Inputs!$B:$B,0)),0)} -> 0 | J10: {=IF(J$3<=INDEX(Inputs!$C:$C,MATCH("End Year",Inputs!$B:$B,0))*12,-J8*INDEX(Inputs!$E:$E,MATCH("*Credit Loss*",Inputs!$B:$B,0)),0)} -> 0 | ... DS10: {=IF(DS$3<=INDEX(Inputs!$C:$C,MATCH("End Year",Inputs!$B:$B,0))*12,-DS8*INDEX(Inputs!$E:$E,MATCH("*Credit Loss*",Inputs!$B:$B,0)),0)} -> 0
B11: Effective Gross Income (EGI) | C11: =C8+C9+C10 -> 0 | D11: =D8+D9+D10 -> 0 | E11: =E8+E9+E10 -> 0 | F11: =F8+F9+F10 -> 0 | G11: =G8+G9+G10 -> 0 | H11: =H8+H9+H10 -> 0 | I11: =I8+I9+I10 -> 0 | J11: =J8+J9+J10 -> 0 | ... DR11: =DR8+DR9+DR10 -> 0
B12: Revenue | C12: {=IF($B12="",0,IF(AND(C$3>=INDEX(Inputs!$C:$C,MATCH("*Revenue Start Month*",Inputs!$B:$B,0)),C$3<=INDEX(Inputs!$C:$C,MATCH("End Year",Inputs!$B:$B,0))*12),IncomeExpenses!$C$47/12*(1+INDEX(Inputs!$C:$C,MATCH("*Annual Revenue Growth Rate*",Inputs!$B:$B,0)))^(C$5-1),0))} -> 0 | D12: {=IF($B12="",0,IF(AND(D$3>=INDEX(Inputs!$C:$C,MATCH("*Revenue Start Month*",Inputs!$B:$B,0)),D$3<=INDEX(Inputs!$C:$C,MATCH("End Year",Inputs!$B:$B,0))*12),IncomeExpenses!$C$47/12*(1+INDEX(Inputs!$C:$C,MATCH("*Annual Revenue Growth Rate*",Inputs!$B:$B,0)))^(D$5-1),0))} -> 0 | E12: {=IF($B12="",0,IF(AND(E$3>=INDEX(Inputs!$C:$C,MATCH("*Revenue Start Month*",Inputs!$B:$B,0)),E$3<=INDEX(Inputs!$C:$C,MATCH("End Year",Inputs!$B:$B,0))*12),IncomeExpenses!$C$47/12*(1+INDEX(Inputs!$C:$C,MATCH("*Annual Revenue Growth Rate*",Inputs!$B:$B,0)))^(E$5-1),0))} -> 0 | F12: {=IF($B12="",0,IF(AND(F$3>=INDEX(Inputs!$C:$C,MATCH("*Revenue Start Month*",Inputs!$B:$B,0)),F$3<=INDEX(Inputs!$C:$C,MATCH("End Year",Inputs!$B:$B,0))*12),IncomeExpenses!$C$47/12*(1+INDEX(Inputs!$C:$C,MATCH("*Annual Revenue Growth Rate*",Inputs!$B:$B,0)))^(F$5-1),0))} -> 0 | G12: {=IF($B12="",0,IF(AND(G$3>=INDEX(Inputs!$C:$C,MATCH("*Revenue Start Month*",Inputs!$B:$B,0)),G$3<=INDEX(Inputs!$C:$C,MATCH("End Year",Inputs!$B:$B,0))*12),IncomeExpenses!$C$47/12*(1+INDEX(Inputs!$C:$C,MATCH("*Annual Revenue Growth Rate*",Inputs!$B:$B,0)))^(G$5-1),0))} -> 0 | H12: {=IF($B12="",0,IF(AND(H$3>=INDEX(Inputs!$C:$C,MATCH("*Revenue Start Month*",Inputs!$B:$B,0)),H$3<=INDEX(Inputs!$C:$C,MATCH("End Year",Inputs!$B:$B,0))*12),IncomeExpenses!$C$47/12*(1+INDEX(Inputs!$C:$C,MATCH("*Annual Revenue Growth Rate*",Inputs!$B:$B,0)))^(H$5-1),0))} -> 0 | I12: {=IF($B12="",0,IF(AND(I$3>=INDEX(Inputs!$C:$C,MATCH("*Revenue Start Month*",Inputs!$B:$B,0)),I$3<=INDEX(Inputs!$C:$C,MATCH("End Year",Inputs!$B:$B,0))*12),IncomeExpenses!$C$47/12*(1+INDEX(Inputs!$C:$C,MATCH("*Annual Revenue Growth Rate*",Inputs!$B:$B,0)))^(I$5-1),0))} -> 0 | J12: {=IF($B12="",0,IF(AND(J$3>=INDEX(Inputs!$C:$C,MATCH("*Revenue Start Month*",Inputs!$B:$B,0)),J$3<=INDEX(Inputs!$C:$C,MATCH("End Year",Inputs!$B:$B,0))*12),IncomeExpenses!$C$47/12*(1+INDEX(Inputs!$C:$C,MATCH("*Annual Revenue Growth Rate*",Inputs!$B:$B,0)))^(J$5-1),0))} -> 0 | ... DS12: {=IF($B12="",0,IF(AND(DS$3>=INDEX(Inputs!$C:$C,MATCH("*Revenue Start Month*",Inputs!$B:$B,0)),DS$3<=INDEX(Inputs!$C:$C,MATCH("End Year",Inputs!$B:$B,0))*12),IncomeExpenses!$C$47/12*(1+INDEX(Inputs!$C:$C,MATCH("*Annual Revenue Growth Rate*",Inputs!$B:$B,0)))^(DS$5-1),0))} -> 0
B13: TOTAL REVENUE | C13: =C11+SUM(C12) -> 0 | D13: =D11+SUM(D12) -> 0 | E13: =E11+SUM(E12) -> 0 | F13: =F11+SUM(F12) -> 0 | G13: =G11+SUM(G12) -> 0 | H13: =H11+SUM(H12) -> 0 | I13: =I11+SUM(I12) -> 0 | J13: =J11+SUM(J12) -> 0 | ... DS13: =DS11+SUM(DS12) -> 0
B15: OPERATING EXPENSES
B16: Property Management Fee (%EGI) | C16: {=IF($B16="",0,IF(AND(C$3>=INDEX(Inputs!$C:$C,MATCH("*Expense Start Month*",Inputs!$B:$B,0)),C$3<=INDEX(Inputs!$C:$C,MATCH("End Year",Inputs!$B:$B,0))*12),IF($B16="Property Management Fee (%EGI)",-C11*Inputs!$C$28,-IncomeExpenses!$C$90/12*(1+INDEX(Inputs!$C:$C,MATCH("*Annual Expense Growth Rate*",Inputs!$B:$B,0)))^(C$5-1)),0))} -> 0 | D16: {=IF($B16="",0,IF(AND(D$3>=INDEX(Inputs!$C:$C,MATCH("*Expense Start Month*",Inputs!$B:$B,0)),D$3<=INDEX(Inputs!$C:$C,MATCH("End Year",Inputs!$B:$B,0))*12),IF($B16="Property Management Fee (%EGI)",-D11*Inputs!$C$28,-IncomeExpenses!$C$90/12*(1+INDEX(Inputs!$C:$C,MATCH("*Annual Expense Growth Rate*",Inputs!$B:$B,0)))^(D$5-1)),0))} -> 0 | E16: {=IF($B16="",0,IF(AND(E$3>=INDEX(Inputs!$C:$C,MATCH("*Expense Start Month*",Inputs!$B:$B,0)),E$3<=INDEX(Inputs!$C:$C,MATCH("End Year",Inputs!$B:$B,0))*12),IF($B16="Property Management Fee (%EGI)",-E11*Inputs!$C$28,-IncomeExpenses!$C$90/12*(1+INDEX(Inputs!$C:$C,MATCH("*Annual Expense Growth Rate*",Inputs!$B:$B,0)))^(E$5-1)),0))} -> 0 | F16: {=IF($B16="",0,IF(AND(F$3>=INDEX(Inputs!$C:$C,MATCH("*Expense Start Month*",Inputs!$B:$B,0)),F$3<=INDEX(Inputs!$C:$C,MATCH("End Year",Inputs!$B:$B,0))*12),IF($B16="Property Management Fee (%EGI)",-F11*Inputs!$C$28,-IncomeExpenses!$C$90/12*(1+INDEX(Inputs!$C:$C,MATCH("*Annual Expense Growth Rate*",Inputs!$B:$B,0)))^(F$5-1)),0))} -> 0 | G16: {=IF($B16="",0,IF(AND(G$3>=INDEX(Inputs!$C:$C,MATCH("*Expense Start Month*",Inputs!$B:$B,0)),G$3<=INDEX(Inputs!$C:$C,MATCH("End Year",Inputs!$B:$B,0))*12),IF($B16="Property Management Fee (%EGI)",-G11*Inputs!$C$28,-IncomeExpenses!$C$90/12*(1+INDEX(Inputs!$C:$C,MATCH("*Annual Expense Growth Rate*",Inputs!$B:$B,0)))^(G$5-1)),0))} -> 0 | H16: {=IF($B16="",0,IF(AND(H$3>=INDEX(Inputs!$C:$C,MATCH("*Expense Start Month*",Inputs!$B:$B,0)),H$3<=INDEX(Inputs!$C:$C,MATCH("End Year",Inputs!$B:$B,0))*12),IF($B16="Property Management Fee (%EGI)",-H11*Inputs!$C$28,-IncomeExpenses!$C$90/12*(1+INDEX(Inputs!$C:$C,MATCH("*Annual Expense Growth Rate*",Inputs!$B:$B,0)))^(H$5-1)),0))} -> 0 | I16: {=IF($B16="",0,IF(AND(I$3>=INDEX(Inputs!$C:$C,MATCH("*Expense Start Month*",Inputs!$B:$B,0)),I$3<=INDEX(Inputs!$C:$C,MATCH("End Year",Inputs!$B:$B,0))*12),IF($B16="Property Management Fee (%EGI)",-I11*Inputs!$C$28,-IncomeExpenses!$C$90/12*(1+INDEX(Inputs!$C:$C,MATCH("*Annual Expense Growth Rate*",Inputs!$B:$B,0)))^(I$5-1)),0))} -> 0 | J16: {=IF($B16="",0,IF(AND(J$3>=INDEX(Inputs!$C:$C,MATCH("*Expense Start Month*",Inputs!$B:$B,0)),J$3<=INDEX(Inputs!$C:$C,MATCH("End Year",Inputs!$B:$B,0))*12),IF($B16="Property Management Fee (%EGI)",-J11*Inputs!$C$28,-IncomeExpenses!$C$90/12*(1+INDEX(Inputs!$C:$C,MATCH("*Annual Expense Growth Rate*",Inputs!$B:$B,0)))^(J$5-1)),0))} -> 0 | ... DS16: {=IF($B16="",0,IF(AND(DS$3>=INDEX(Inputs!$C:$C,MATCH("*Expense Start Month*",Inputs!$B:$B,0)),DS$3<=INDEX(Inputs!$C:$C,MATCH("End Year",Inputs!$B:$B,0))*12),IF($B16="Property Management Fee (%EGI)",-DS11*Inputs!$C$28,-IncomeExpenses!$C$90/12*(1+INDEX(Inputs!$C:$C,MATCH("*Annual Expense Growth Rate*",Inputs!$B:$B,0)))^(DS$5-1)),0))} -> 0
B17: Expenses | C17: {=IF($B17="",0,IF(AND(C$3>=INDEX(Inputs!$C:$C,MATCH("*Expense Start Month*",Inputs!$B:$B,0)),C$3<=INDEX(Inputs!$C:$C,MATCH("End Year",Inputs!$B:$B,0))*12),IF($B17="Property Management Fee (%EGI)",-C11*Inputs!$C$28,-IncomeExpenses!$C$90/12*(1+INDEX(Inputs!$C:$C,MATCH("*Annual Expense Growth Rate*",Inputs!$B:$B,0)))^(C$5-1)),0))} -> 0 | D17: {=IF($B17="",0,IF(AND(D$3>=INDEX(Inputs!$C:$C,MATCH("*Expense Start Month*",Inputs!$B:$B,0)),D$3<=INDEX(Inputs!$C:$C,MATCH("End Year",Inputs!$B:$B,0))*12),IF($B17="Property Management Fee (%EGI)",-D11*Inputs!$C$28,-IncomeExpenses!$C$90/12*(1+INDEX(Inputs!$C:$C,MATCH("*Annual Expense Growth Rate*",Inputs!$B:$B,0)))^(D$5-1)),0))} -> 0 | E17: {=IF($B17="",0,IF(AND(E$3>=INDEX(Inputs!$C:$C,MATCH("*Expense Start Month*",Inputs!$B:$B,0)),E$3<=INDEX(Inputs!$C:$C,MATCH("End Year",Inputs!$B:$B,0))*12),IF($B17="Property Management Fee (%EGI)",-E11*Inputs!$C$28,-IncomeExpenses!$C$90/12*(1+INDEX(Inputs!$C:$C,MATCH("*Annual Expense Growth Rate*",Inputs!$B:$B,0)))^(E$5-1)),0))} -> 0 | F17: {=IF($B17="",0,IF(AND(F$3>=INDEX(Inputs!$C:$C,MATCH("*Expense Start Month*",Inputs!$B:$B,0)),F$3<=INDEX(Inputs!$C:$C,MATCH("End Year",Inputs!$B:$B,0))*12),IF($B17="Property Management Fee (%EGI)",-F11*Inputs!$C$28,-IncomeExpenses!$C$90/12*(1+INDEX(Inputs!$C:$C,MATCH("*Annual Expense Growth Rate*",Inputs!$B:$B,0)))^(F$5-1)),0))} -> 0 | G17: {=IF($B17="",0,IF(AND(G$3>=INDEX(Inputs!$C:$C,MATCH("*Expense Start Month*",Inputs!$B:$B,0)),G$3<=INDEX(Inputs!$C:$C,MATCH("End Year",Inputs!$B:$B,0))*12),IF($B17="Property Management Fee (%EGI)",-G11*Inputs!$C$28,-IncomeExpenses!$C$90/12*(1+INDEX(Inputs!$C:$C,MATCH("*Annual Expense Growth Rate*",Inputs!$B:$B,0)))^(G$5-1)),0))} -> 0 | H17: {=IF($B17="",0,IF(AND(H$3>=INDEX(Inputs!$C:$C,MATCH("*Expense Start Month*",Inputs!$B:$B,0)),H$3<=INDEX(Inputs!$C:$C,MATCH("End Year",Inputs!$B:$B,0))*12),IF($B17="Property Management Fee (%EGI)",-H11*Inputs!$C$28,-IncomeExpenses!$C$90/12*(1+INDEX(Inputs!$C:$C,MATCH("*Annual Expense Growth Rate*",Inputs!$B:$B,0)))^(H$5-1)),0))} -> 0 | I17: {=IF($B17="",0,IF(AND(I$3>=INDEX(Inputs!$C:$C,MATCH("*Expense Start Month*",Inputs!$B:$B,0)),I$3<=INDEX(Inputs!$C:$C,MATCH("End Year",Inputs!$B:$B,0))*12),IF($B17="Property Management Fee (%EGI)",-I11*Inputs!$C$28,-IncomeExpenses!$C$90/12*(1+INDEX(Inputs!$C:$C,MATCH("*Annual Expense Growth Rate*",Inputs!$B:$B,0)))^(I$5-1)),0))} -> 0 | J17: {=IF($B17="",0,IF(AND(J$3>=INDEX(Inputs!$C:$C,MATCH("*Expense Start Month*",Inputs!$B:$B,0)),J$3<=INDEX(Inputs!$C:$C,MATCH("End Year",Inputs!$B:$B,0))*12),IF($B17="Property Management Fee (%EGI)",-J11*Inputs!$C$28,-IncomeExpenses!$C$90/12*(1+INDEX(Inputs!$C:$C,MATCH("*Annual Expense Growth Rate*",Inputs!$B:$B,0)))^(J$5-1)),0))} -> 0 | ... DS17: {=IF($B17="",0,IF(AND(DS$3>=INDEX(Inputs!$C:$C,MATCH("*Expense Start Month*",Inputs!$B:$B,0)),DS$3<=INDEX(Inputs!$C:$C,MATCH("End Year",Inputs!$B:$B,0))*12),IF($B17="Property Management Fee (%EGI)",-DS11*Inputs!$C$28,-IncomeExpenses!$C$90/12*(1+INDEX(Inputs!$C:$C,MATCH("*Annual Expense Growth Rate*",Inputs!$B:$B,0)))^(DS$5-1)),0))} -> 0
B18: TOTAL OPERATING EXPENSES | C18: =SUM(C16:C17) -> 0 | D18: =SUM(D16:D17) -> 0 | E18: =SUM(E16:E17) -> 0 | F18: =SUM(F16:F17) -> 0 | G18: =SUM(G16:G17) -> 0 | H18: =SUM(H16:H17) -> 0 | I18: =SUM(I16:I17) -> 0 | J18: =SUM(J16:J17) -> 0 | ... DS18: =SUM(DS16:DS17) -> 0
B20: NET OPERATING INCOME (NOI) | C20: =C13+C18 -> 0 | D20: =D13+D18 -> 0 | E20: =E13+E18 -> 0 | F20: =F13+F18 -> 0 | G20: =G13+G18 -> 0 | H20: =H13+H18 -> 0 | I20: =I13+I18 -> 0 | J20: =J13+J18 -> 0 | ... DS20: =DS13+DS18 -> 0
B22: CAPITAL EXPENDITURES
B23: Capital Expenditures (CapEx) | C23: {=IF(C$3<=INDEX(Inputs!$C:$C,MATCH("End Year",Inputs!$B:$B,0))*12,-SUMIFS(Inputs!$C:$C,Inputs!$B:$B,"*CapEx Item*",Inputs!$D:$D,C$3),0)} -> 0 | D23: {=IF(D$3<=INDEX(Inputs!$C:$C,MATCH("End Year",Inputs!$B:$B,0))*12,-SUMIFS(Inputs!$C:$C,Inputs!$B:$B,"*CapEx Item*",Inputs!$D:$D,D$3),0)} -> 0 | E23: {=IF(E$3<=INDEX(Inputs!$C:$C,MATCH("End Year",Inputs!$B:$B,0))*12,-SUMIFS(Inputs!$C:$C,Inputs!$B:$B,"*CapEx Item*",Inputs!$D:$D,E$3),0)} -> 0 | F23: {=IF(F$3<=INDEX(Inputs!$C:$C,MATCH("End Year",Inputs!$B:$B,0))*12,-SUMIFS(Inputs!$C:$C,Inputs!$B:$B,"*CapEx Item*",Inputs!$D:$D,F$3),0)} -> 0 | G23: {=IF(G$3<=INDEX(Inputs!$C:$C,MATCH("End Year",Inputs!$B:$B,0))*12,-SUMIFS(Inputs!$C:$C,Inputs!$B:$B,"*CapEx Item*",Inputs!$D:$D,G$3),0)} -> 0 | H23: {=IF(H$3<=INDEX(Inputs!$C:$C,MATCH("End Year",Inputs!$B:$B,0))*12,-SUMIFS(Inputs!$C:$C,Inputs!$B:$B,"*CapEx Item*",Inputs!$D:$D,H$3),0)} -> 0 | I23: {=IF(I$3<=INDEX(Inputs!$C:$C,MATCH("End Year",Inputs!$B:$B,0))*12,-SUMIFS(Inputs!$C:$C,Inputs!$B:$B,"*CapEx Item*",Inputs!$D:$D,I$3),0)} -> 0 | J23: {=IF(J$3<=INDEX(Inputs!$C:$C,MATCH("End Year",Inputs!$B:$B,0))*12,-SUMIFS(Inputs!$C:$C,Inputs!$B:$B,"*CapEx Item*",Inputs!$D:$D,J$3),0)} -> 0 | ... DS23: {=IF(DS$3<=INDEX(Inputs!$C:$C,MATCH("End Year",Inputs!$B:$B,0))*12,-SUMIFS(Inputs!$C:$C,Inputs!$B:$B,"*CapEx Item*",Inputs!$D:$D,DS$3),0)} -> 0
B25: ACQUISITION
B26: Purchase Price | C26: {=IF(C$3=1,-INDEX(Inputs!$C:$C,MATCH("*Purchase Price*",Inputs!$B:$B,0)),0)} -> 0 | D26: {=IF(D$3=1,-INDEX(Inputs!$C:$C,MATCH("*Purchase Price*",Inputs!$B:$B,0)),0)} -> 0 | E26: {=IF(E$3=1,-INDEX(Inputs!$C:$C,MATCH("*Purchase Price*",Inputs!$B:$B,0)),0)} -> 0 | F26: {=IF(F$3=1,-INDEX(Inputs!$C:$C,MATCH("*Purchase Price*",Inputs!$B:$B,0)),0)} -> 0 | G26: {=IF(G$3=1,-INDEX(Inputs!$C:$C,MATCH("*Purchase Price*",Inputs!$B:$B,0)),0)} -> 0 | H26: {=IF(H$3=1,-INDEX(Inputs!$C:$C,MATCH("*Purchase Price*",Inputs!$B:$B,0)),0)} -> 0 | I26: {=IF(I$3=1,-INDEX(Inputs!$C:$C,MATCH("*Purchase Price*",Inputs!$B:$B,0)),0)} -> 0 | J26: {=IF(J$3=1,-INDEX(Inputs!$C:$C,MATCH("*Purchase Price*",Inputs!$B:$B,0)),0)} -> 0 | ... DS26: {=IF(DS$3=1,-INDEX(Inputs!$C:$C,MATCH("*Purchase Price*",Inputs!$B:$B,0)),0)} -> 0
B27: Closing Costs | C27: =IF(C$3=1,-Inputs!C85,0) -> 0 | D27: =IF(D$3=1,-Inputs!C85,0) -> 0 | E27: =IF(E$3=1,-Inputs!C85,0) -> 0 | F27: =IF(F$3=1,-Inputs!C85,0) -> 0 | G27: =IF(G$3=1,-Inputs!C85,0) -> 0 | H27: =IF(H$3=1,-Inputs!C85,0) -> 0 | I27: =IF(I$3=1,-Inputs!C85,0) -> 0 | J27: =IF(J$3=1,-Inputs!C85,0) -> 0 | K27: =IF(K$3=1,-Inputs!C85,0) -> 0 | L27: =IF(L$3=1,-Inputs!C85,0) -> 0 | M27: =IF(M$3=1,-Inputs!C85,0) -> 0 | N27: =IF(N$3=1,-Inputs!C85,0) -> 0 | O27: =IF(O$3=1,-Inputs!C85,0) -> 0 | P27: =IF(P$3=1,-Inputs!C85,0) -> 0 | Q27: =IF(Q$3=1,-Inputs!C85,0) -> 0 | R27: =IF(R$3=1,-Inputs!C85,0) -> 0 | S27: =IF(S$3=1,-Inputs!C85,0) -> 0 | T27: =IF(T$3=1,-Inputs!C85,0) -> 0 | U27: =IF(U$3=1,-Inputs!C85,0) -> 0 | V27: =IF(V$3=1,-Inputs!C85,0) -> 0 | W27: =IF(W$3=1,-Inputs!C85,0) -> 0 | X27: =IF(X$3=1,-Inputs!C85,0) -> 0 | Y27: =IF(Y$3=1,-Inputs!C85,0) -> 0 | Z27: =IF(Z$3=1,-Inputs!C85,0) -> 0 | AA27: =IF(AA$3=1,-Inputs!C85,0) -> 0 | AB27: =IF(AB$3=1,-Inputs!C85,0) -> 0 | AC27: =IF(AC$3=1,-Inputs!C85,0) -> 0 | AD27: =IF(AD$3=1,-Inputs!C85,0) -> 0 | AE27: =IF(AE$3=1,-Inputs!C85,0) -> 0 | AF27: =IF(AF$3=1,-Inputs!C85,0) -> 0 | AG27: =IF(AG$3=1,-Inputs!C85,0) -> 0 | AH27: =IF(AH$3=1,-Inputs!C85,0) -> 0 | AI27: =IF(AI$3=1,-Inputs!C85,0) -> 0 | AJ27: =IF(AJ$3=1,-Inputs!C85,0) -> 0 | AK27: =IF(AK$3=1,-Inputs!C85,0) -> 0 | AL27: =IF(AL$3=1,-Inputs!C85,0) -> 0 | AM27: =IF(AM$3=1,-Inputs!C85,0) -> 0 | AN27: =IF(AN$3=1,-Inputs!C85,0) -> 0 | AO27: =IF(AO$3=1,-Inputs!C85,0) -> 0 | AP27: =IF(AP$3=1,-Inputs!C85,0) -> 0 | AQ27: =IF(AQ$3=1,-Inputs!C85,0) -> 0 | AR27: =IF(AR$3=1,-Inputs!C85,0) -> 0 | AS27: =IF(AS$3=1,-Inputs!C85,0) -> 0 | AT27: =IF(AT$3=1,-Inputs!C85,0) -> 0 | AU27: =IF(AU$3=1,-Inputs!C85,0) -> 0 | AV27: =IF(AV$3=1,-Inputs!C85,0) -> 0 | AW27: =IF(AW$3=1,-Inputs!C85,0) -> 0 | AX27: =IF(AX$3=1,-Inputs!C85,0) -> 0 | AY27: =IF(AY$3=1,-Inputs!C85,0) -> 0 | AZ27: =IF(AZ$3=1,-Inputs!C85,0) -> 0 | BA27: =IF(BA$3=1,-Inputs!C85,0) -> 0 | BB27: =IF(BB$3=1,-Inputs!C85,0) -> 0 | BC27: =IF(BC$3=1,-Inputs!C85,0) -> 0 | BD27: =IF(BD$3=1,-Inputs!C85,0) -> 0 | BE27: =IF(BE$3=1,-Inputs!C85,0) -> 0 | BF27: =IF(BF$3=1,-Inputs!C85,0) -> 0 | BG27: =IF(BG$3=1,-Inputs!C85,0) -> 0 | BH27: =IF(BH$3=1,-Inputs!C85,0) -> 0 | BI27: =IF(BI$3=1,-Inputs!C85,0) -> 0 | BJ27: =IF(BJ$3=1,-Inputs!C85,0) -> 0 | BK27: =IF(BK$3=1,-Inputs!C85,0) -> 0 | BL27: =IF(BL$3=1,-Inputs!C85,0) -> 0 | BM27: =IF(BM$3=1,-Inputs!C85,0) -> 0 | BN27: =IF(BN$3=1,-Inputs!C85,0) -> 0 | BO27: =IF(BO$3=1,-Inputs!C85,0) -> 0 | BP27: =IF(BP$3=1,-Inputs!C85,0) -> 0 | BQ27: =IF(BQ$3=1,-Inputs!C85,0) -> 0 | BR27: =IF(BR$3=1,-Inputs!C85,0) -> 0 | BS27: =IF(BS$3=1,-Inputs!C85,0) -> 0 | BT27: =IF(BT$3=1,-Inputs!C85,0) -> 0 | BU27: =IF(BU$3=1,-Inputs!C85,0) -> 0 | BV27: =IF(BV$3=1,-Inputs!C85,0) -> 0 | BW27: =IF(BW$3=1,-Inputs!C85,0) -> 0 | BX27: =IF(BX$3=1,-Inputs!C85,0) -> 0 | BY27: =IF(BY$3=1,-Inputs!C85,0) -> 0 | BZ27: =IF(BZ$3=1,-Inputs!C85,0) -> 0 | CA27: =IF(CA$3=1,-Inputs!C85,0) -> 0 | CB27: =IF(CB$3=1,-Inputs!C85,0) -> 0 | CC27: =IF(CC$3=1,-Inputs!C85,0) -> 0 | CD27: =IF(CD$3=1,-Inputs!C85,0) -> 0 | CE27: =IF(CE$3=1,-Inputs!C85,0) -> 0 | CF27: =IF(CF$3=1,-Inputs!C85,0) -> 0 | CG27: =IF(CG$3=1,-Inputs!C85,0) -> 0 | CH27: =IF(CH$3=1,-Inputs!C85,0) -> 0 | CI27: =IF(CI$3=1,-Inputs!C85,0) -> 0 | CJ27: =IF(CJ$3=1,-Inputs!C85,0) -> 0 | CK27: =IF(CK$3=1,-Inputs!C85,0) -> 0 | CL27: =IF(CL$3=1,-Inputs!C85,0) -> 0 | CM27: =IF(CM$3=1,-Inputs!C85,0) -> 0 | CN27: =IF(CN$3=1,-Inputs!C85,0) -> 0 | CO27: =IF(CO$3=1,-Inputs!C85,0) -> 0 | CP27: =IF(CP$3=1,-Inputs!C85,0) -> 0 | CQ27: =IF(CQ$3=1,-Inputs!C85,0) -> 0 | CR27: =IF(CR$3=1,-Inputs!C85,0) -> 0 | CS27: =IF(CS$3=1,-Inputs!C85,0) -> 0 | CT27: =IF(CT$3=1,-Inputs!C85,0) -> 0 | CU27: =IF(CU$3=1,-Inputs!C85,0) -> 0 | CV27: =IF(CV$3=1,-Inputs!C85,0) -> 0 | CW27: =IF(CW$3=1,-Inputs!C85,0) -> 0 | CX27: =IF(CX$3=1,-Inputs!C85,0) -> 0 | CY27: =IF(CY$3=1,-Inputs!C85,0) -> 0 | CZ27: =IF(CZ$3=1,-Inputs!C85,0) -> 0 | DA27: =IF(DA$3=1,-Inputs!C85,0) -> 0 | DB27: =IF(DB$3=1,-Inputs!C85,0) -> 0 | DC27: =IF(DC$3=1,-Inputs!C85,0) -> 0 | DD27: =IF(DD$3=1,-Inputs!C85,0) -> 0 | DE27: =IF(DE$3=1,-Inputs!C85,0) -> 0 | DF27: =IF(DF$3=1,-Inputs!C85,0) -> 0 | DG27: =IF(DG$3=1,-Inputs!C85,0) -> 0 | DH27: =IF(DH$3=1,-Inputs!C85,0) -> 0 | DI27: =IF(DI$3=1,-Inputs!C85,0) -> 0 | DJ27: =IF(DJ$3=1,-Inputs!C85,0) -> 0 | DK27: =IF(DK$3=1,-Inputs!C85,0) -> 0 | DL27: =IF(DL$3=1,-Inputs!C85,0) -> 0 | DM27: =IF(DM$3=1,-Inputs!C85,0) -> 0 | DN27: =IF(DN$3=1,-Inputs!C85,0) -> 0 | DO27: =IF(DO$3=1,-Inputs!C85,0) -> 0 | DP27: =IF(DP$3=1,-Inputs!C85,0) -> 0 | DQ27: =IF(DQ$3=1,-Inputs!C85,0) -> 0 | DR27: =IF(DR$3=1,-Inputs!C85,0) -> 0 | DS27: =IF(DS$3=1,-Inputs!C85,0) -> 0
B28: Immediate Repairs / Reserves | C28: =IF(C$3=1,-Inputs!C86,0) -> -5000 | D28: =IF(D$3=1,-Inputs!C86,0) -> 0 | E28: =IF(E$3=1,-Inputs!C86,0) -> 0 | F28: =IF(F$3=1,-Inputs!C86,0) -> 0 | G28: =IF(G$3=1,-Inputs!C86,0) -> 0 | H28: =IF(H$3=1,-Inputs!C86,0) -> 0 | I28: =IF(I$3=1,-Inputs!C86,0) -> 0 | J28: =IF(J$3=1,-Inputs!C86,0) -> 0 | K28: =IF(K$3=1,-Inputs!C86,0) -> 0 | L28: =IF(L$3=1,-Inputs!C86,0) -> 0 | M28: =IF(M$3=1,-Inputs!C86,0) -> 0 | N28: =IF(N$3=1,-Inputs!C86,0) -> 0 | O28: =IF(O$3=1,-Inputs!C86,0) -> 0 | P28: =IF(P$3=1,-Inputs!C86,0) -> 0 | Q28: =IF(Q$3=1,-Inputs!C86,0) -> 0 | R28: =IF(R$3=1,-Inputs!C86,0) -> 0 | S28: =IF(S$3=1,-Inputs!C86,0) -> 0 | T28: =IF(T$3=1,-Inputs!C86,0) -> 0 | U28: =IF(U$3=1,-Inputs!C86,0) -> 0 | V28: =IF(V$3=1,-Inputs!C86,0) -> 0 | W28: =IF(W$3=1,-Inputs!C86,0) -> 0 | X28: =IF(X$3=1,-Inputs!C86,0) -> 0 | Y28: =IF(Y$3=1,-Inputs!C86,0) -> 0 | Z28: =IF(Z$3=1,-Inputs!C86,0) -> 0 | AA28: =IF(AA$3=1,-Inputs!C86,0) -> 0 | AB28: =IF(AB$3=1,-Inputs!C86,0) -> 0 | AC28: =IF(AC$3=1,-Inputs!C86,0) -> 0 | AD28: =IF(AD$3=1,-Inputs!C86,0) -> 0 | AE28: =IF(AE$3=1,-Inputs!C86,0) -> 0 | AF28: =IF(AF$3=1,-Inputs!C86,0) -> 0 | AG28: =IF(AG$3=1,-Inputs!C86,0) -> 0 | AH28: =IF(AH$3=1,-Inputs!C86,0) -> 0 | AI28: =IF(AI$3=1,-Inputs!C86,0) -> 0 | AJ28: =IF(AJ$3=1,-Inputs!C86,0) -> 0 | AK28: =IF(AK$3=1,-Inputs!C86,0) -> 0 | AL28: =IF(AL$3=1,-Inputs!C86,0) -> 0 | AM28: =IF(AM$3=1,-Inputs!C86,0) -> 0 | AN28: =IF(AN$3=1,-Inputs!C86,0) -> 0 | AO28: =IF(AO$3=1,-Inputs!C86,0) -> 0 | AP28: =IF(AP$3=1,-Inputs!C86,0) -> 0 | AQ28: =IF(AQ$3=1,-Inputs!C86,0) -> 0 | AR28: =IF(AR$3=1,-Inputs!C86,0) -> 0 | AS28: =IF(AS$3=1,-Inputs!C86,0) -> 0 | AT28: =IF(AT$3=1,-Inputs!C86,0) -> 0 | AU28: =IF(AU$3=1,-Inputs!C86,0) -> 0 | AV28: =IF(AV$3=1,-Inputs!C86,0) -> 0 | AW28: =IF(AW$3=1,-Inputs!C86,0) -> 0 | AX28: =IF(AX$3=1,-Inputs!C86,0) -> 0 | AY28: =IF(AY$3=1,-Inputs!C86,0) -> 0 | AZ28: =IF(AZ$3=1,-Inputs!C86,0) -> 0 | BA28: =IF(BA$3=1,-Inputs!C86,0) -> 0 | BB28: =IF(BB$3=1,-Inputs!C86,0) -> 0 | BC28: =IF(BC$3=1,-Inputs!C86,0) -> 0 | BD28: =IF(BD$3=1,-Inputs!C86,0) -> 0 | BE28: =IF(BE$3=1,-Inputs!C86,0) -> 0 | BF28: =IF(BF$3=1,-Inputs!C86,0) -> 0 | BG28: =IF(BG$3=1,-Inputs!C86,0) -> 0 | BH28: =IF(BH$3=1,-Inputs!C86,0) -> 0 | BI28: =IF(BI$3=1,-Inputs!C86,0) -> 0 | BJ28: =IF(BJ$3=1,-Inputs!C86,0) -> 0 | BK28: =IF(BK$3=1,-Inputs!C86,0) -> 0 | BL28: =IF(BL$3=1,-Inputs!C86,0) -> 0 | BM28: =IF(BM$3=1,-Inputs!C86,0) -> 0 | BN28: =IF(BN$3=1,-Inputs!C86,0) -> 0 | BO28: =IF(BO$3=1,-Inputs!C86,0) -> 0 | BP28: =IF(BP$3=1,-Inputs!C86,0) -> 0 | BQ28: =IF(BQ$3=1,-Inputs!C86,0) -> 0 | BR28: =IF(BR$3=1,-Inputs!C86,0) -> 0 | BS28: =IF(BS$3=1,-Inputs!C86,0) -> 0 | BT28: =IF(BT$3=1,-Inputs!C86,0) -> 0 | BU28: =IF(BU$3=1,-Inputs!C86,0) -> 0 | BV28: =IF(BV$3=1,-Inputs!C86,0) -> 0 | BW28: =IF(BW$3=1,-Inputs!C86,0) -> 0 | BX28: =IF(BX$3=1,-Inputs!C86,0) -> 0 | BY28: =IF(BY$3=1,-Inputs!C86,0) -> 0 | BZ28: =IF(BZ$3=1,-Inputs!C86,0) -> 0 | CA28: =IF(CA$3=1,-Inputs!C86,0) -> 0 | CB28: =IF(CB$3=1,-Inputs!C86,0) -> 0 | CC28: =IF(CC$3=1,-Inputs!C86,0) -> 0 | CD28: =IF(CD$3=1,-Inputs!C86,0) -> 0 | CE28: =IF(CE$3=1,-Inputs!C86,0) -> 0 | CF28: =IF(CF$3=1,-Inputs!C86,0) -> 0 | CG28: =IF(CG$3=1,-Inputs!C86,0) -> 0 | CH28: =IF(CH$3=1,-Inputs!C86,0) -> 0 | CI28: =IF(CI$3=1,-Inputs!C86,0) -> 0 | CJ28: =IF(CJ$3=1,-Inputs!C86,0) -> 0 | CK28: =IF(CK$3=1,-Inputs!C86,0) -> 0 | CL28: =IF(CL$3=1,-Inputs!C86,0) -> 0 | CM28: =IF(CM$3=1,-Inputs!C86,0) -> 0 | CN28: =IF(CN$3=1,-Inputs!C86,0) -> 0 | CO28: =IF(CO$3=1,-Inputs!C86,0) -> 0 | CP28: =IF(CP$3=1,-Inputs!C86,0) -> 0 | CQ28: =IF(CQ$3=1,-Inputs!C86,0) -> 0 | CR28: =IF(CR$3=1,-Inputs!C86,0) -> 0 | CS28: =IF(CS$3=1,-Inputs!C86,0) -> 0 | CT28: =IF(CT$3=1,-Inputs!C86,0) -> 0 | CU28: =IF(CU$3=1,-Inputs!C86,0) -> 0 | CV28: =IF(CV$3=1,-Inputs!C86,0) -> 0 | CW28: =IF(CW$3=1,-Inputs!C86,0) -> 0 | CX28: =IF(CX$3=1,-Inputs!C86,0) -> 0 | CY28: =IF(CY$3=1,-Inputs!C86,0) -> 0 | CZ28: =IF(CZ$3=1,-Inputs!C86,0) -> 0 | DA28: =IF(DA$3=1,-Inputs!C86,0) -> 0 | DB28: =IF(DB$3=1,-Inputs!C86,0) -> 0 | DC28: =IF(DC$3=1,-Inputs!C86,0) -> 0 | DD28: =IF(DD$3=1,-Inputs!C86,0) -> 0 | DE28: =IF(DE$3=1,-Inputs!C86,0) -> 0 | DF28: =IF(DF$3=1,-Inputs!C86,0) -> 0 | DG28: =IF(DG$3=1,-Inputs!C86,0) -> 0 | DH28: =IF(DH$3=1,-Inputs!C86,0) -> 0 | DI28: =IF(DI$3=1,-Inputs!C86,0) -> 0 | DJ28: =IF(DJ$3=1,-Inputs!C86,0) -> 0 | DK28: =IF(DK$3=1,-Inputs!C86,0) -> 0 | DL28: =IF(DL$3=1,-Inputs!C86,0) -> 0 | DM28: =IF(DM$3=1,-Inputs!C86,0) -> 0 | DN28: =IF(DN$3=1,-Inputs!C86,0) -> 0 | DO28: =IF(DO$3=1,-Inputs!C86,0) -> 0 | DP28: =IF(DP$3=1,-Inputs!C86,0) -> 0 | DQ28: =IF(DQ$3=1,-Inputs!C86,0) -> 0 | DR28: =IF(DR$3=1,-Inputs!C86,0) -> 0 | DS28: =IF(DS$3=1,-Inputs!C86,0) -> 0
B29: Acquisition Fee | C29: {=IF(C$3=1,-INDEX(Inputs!$C:$C,MATCH("*Purchase Price*",Inputs!$B:$B,0))*Inputs!C93,0)} -> 0 | D29: {=IF(D$3=1,-INDEX(Inputs!$C:$C,MATCH("*Purchase Price*",Inputs!$B:$B,0))*Inputs!C93,0)} -> 0 | E29: {=IF(E$3=1,-INDEX(Inputs!$C:$C,MATCH("*Purchase Price*",Inputs!$B:$B,0))*Inputs!C93,0)} -> 0 | F29: {=IF(F$3=1,-INDEX(Inputs!$C:$C,MATCH("*Purchase Price*",Inputs!$B:$B,0))*Inputs!C93,0)} -> 0 | G29: {=IF(G$3=1,-INDEX(Inputs!$C:$C,MATCH("*Purchase Price*",Inputs!$B:$B,0))*Inputs!C93,0)} -> 0 | H29: {=IF(H$3=1,-INDEX(Inputs!$C:$C,MATCH("*Purchase Price*",Inputs!$B:$B,0))*Inputs!C93,0)} -> 0 | I29: {=IF(I$3=1,-INDEX(Inputs!$C:$C,MATCH("*Purchase Price*",Inputs!$B:$B,0))*Inputs!C93,0)} -> 0 | J29: {=IF(J$3=1,-INDEX(Inputs!$C:$C,MATCH("*Purchase Price*",Inputs!$B:$B,0))*Inputs!C93,0)} -> 0 | K29: {=IF(K$3=1,-INDEX(Inputs!$C:$C,MATCH("*Purchase Price*",Inputs!$B:$B,0))*Inputs!C93,0)} -> 0 | L29: {=IF(L$3=1,-INDEX(Inputs!$C:$C,MATCH("*Purchase Price*",Inputs!$B:$B,0))*Inputs!C93,0)} -> 0 | M29: {=IF(M$3=1,-INDEX(Inputs!$C:$C,MATCH("*Purchase Price*",Inputs!$B:$B,0))*Inputs!C93,0)} -> 0 | N29: {=IF(N$3=1,-INDEX(Inputs!$C:$C,MATCH("*Purchase Price*",Inputs!$B:$B,0))*Inputs!C93,0)} -> 0 | O29: {=IF(O$3=1,-INDEX(Inputs!$C:$C,MATCH("*Purchase Price*",Inputs!$B:$B,0))*Inputs!C93,0)} -> 0 | P29: {=IF(P$3=1,-INDEX(Inputs!$C:$C,MATCH("*Purchase Price*",Inputs!$B:$B,0))*Inputs!C93,0)} -> 0 | Q29: {=IF(Q$3=1,-INDEX(Inputs!$C:$C,MATCH("*Purchase Price*",Inputs!$B:$B,0))*Inputs!C93,0)} -> 0 | R29: {=IF(R$3=1,-INDEX(Inputs!$C:$C,MATCH("*Purchase Price*",Inputs!$B:$B,0))*Inputs!C93,0)} -> 0 | S29: {=IF(S$3=1,-INDEX(Inputs!$C:$C,MATCH("*Purchase Price*",Inputs!$B:$B,0))*Inputs!C93,0)} -> 0 | T29: {=IF(T$3=1,-INDEX(Inputs!$C:$C,MATCH("*Purchase Price*",Inputs!$B:$B,0))*Inputs!C93,0)} -> 0 | U29: {=IF(U$3=1,-INDEX(Inputs!$C:$C,MATCH("*Purchase Price*",Inputs!$B:$B,0))*Inputs!C93,0)} -> 0 | V29: {=IF(V$3=1,-INDEX(Inputs!$C:$C,MATCH("*Purchase Price*",Inputs!$B:$B,0))*Inputs!C93,0)} -> 0 | W29: {=IF(W$3=1,-INDEX(Inputs!$C:$C,MATCH("*Purchase Price*",Inputs!$B:$B,0))*Inputs!C93,0)} -> 0 | X29: {=IF(X$3=1,-INDEX(Inputs!$C:$C,MATCH("*Purchase Price*",Inputs!$B:$B,0))*Inputs!C93,0)} -> 0 | Y29: {=IF(Y$3=1,-INDEX(Inputs!$C:$C,MATCH("*Purchase Price*",Inputs!$B:$B,0))*Inputs!C93,0)} -> 0 | Z29: {=IF(Z$3=1,-INDEX(Inputs!$C:$C,MATCH("*Purchase Price*",Inputs!$B:$B,0))*Inputs!C93,0)} -> 0 | AA29: {=IF(AA$3=1,-INDEX(Inputs!$C:$C,MATCH("*Purchase Price*",Inputs!$B:$B,0))*Inputs!C93,0)} -> 0 | AB29: {=IF(AB$3=1,-INDEX(Inputs!$C:$C,MATCH("*Purchase Price*",Inputs!$B:$B,0))*Inputs!C93,0)} -> 0 | AC29: {=IF(AC$3=1,-INDEX(Inputs!$C:$C,MATCH("*Purchase Price*",Inputs!$B:$B,0))*Inputs!C93,0)} -> 0 | AD29: {=IF(AD$3=1,-INDEX(Inputs!$C:$C,MATCH("*Purchase Price*",Inputs!$B:$B,0))*Inputs!C93,0)} -> 0 | AE29: {=IF(AE$3=1,-INDEX(Inputs!$C:$C,MATCH("*Purchase Price*",Inputs!$B:$B,0))*Inputs!C93,0)} -> 0 | AF29: {=IF(AF$3=1,-INDEX(Inputs!$C:$C,MATCH("*Purchase Price*",Inputs!$B:$B,0))*Inputs!C93,0)} -> 0 | AG29: {=IF(AG$3=1,-INDEX(Inputs!$C:$C,MATCH("*Purchase Price*",Inputs!$B:$B,0))*Inputs!C93,0)} -> 0 | AH29: {=IF(AH$3=1,-INDEX(Inputs!$C:$C,MATCH("*Purchase Price*",Inputs!$B:$B,0))*Inputs!C93,0)} -> 0 | AI29: {=IF(AI$3=1,-INDEX(Inputs!$C:$C,MATCH("*Purchase Price*",Inputs!$B:$B,0))*Inputs!C93,0)} -> 0 | AJ29: {=IF(AJ$3=1,-INDEX(Inputs!$C:$C,MATCH("*Purchase Price*",Inputs!$B:$B,0))*Inputs!C93,0)} -> 0 | AK29: {=IF(AK$3=1,-INDEX(Inputs!$C:$C,MATCH("*Purchase Price*",Inputs!$B:$B,0))*Inputs!C93,0)} -> 0 | AL29: {=IF(AL$3=1,-INDEX(Inputs!$C:$C,MATCH("*Purchase Price*",Inputs!$B:$B,0))*Inputs!C93,0)} -> 0 | AM29: {=IF(AM$3=1,-INDEX(Inputs!$C:$C,MATCH("*Purchase Price*",Inputs!$B:$B,0))*Inputs!C93,0)} -> 0 | AN29: {=IF(AN$3=1,-INDEX(Inputs!$C:$C,MATCH("*Purchase Price*",Inputs!$B:$B,0))*Inputs!C93,0)} -> 0 | AO29: {=IF(AO$3=1,-INDEX(Inputs!$C:$C,MATCH("*Purchase Price*",Inputs!$B:$B,0))*Inputs!C93,0)} -> 0 | AP29: {=IF(AP$3=1,-INDEX(Inputs!$C:$C,MATCH("*Purchase Price*",Inputs!$B:$B,0))*Inputs!C93,0)} -> 0 | AQ29: {=IF(AQ$3=1,-INDEX(Inputs!$C:$C,MATCH("*Purchase Price*",Inputs!$B:$B,0))*Inputs!C93,0)} -> 0 | AR29: {=IF(AR$3=1,-INDEX(Inputs!$C:$C,MATCH("*Purchase Price*",Inputs!$B:$B,0))*Inputs!C93,0)} -> 0 | AS29: {=IF(AS$3=1,-INDEX(Inputs!$C:$C,MATCH("*Purchase Price*",Inputs!$B:$B,0))*Inputs!C93,0)} -> 0 | AT29: {=IF(AT$3=1,-INDEX(Inputs!$C:$C,MATCH("*Purchase Price*",Inputs!$B:$B,0))*Inputs!C93,0)} -> 0 | AU29: {=IF(AU$3=1,-INDEX(Inputs!$C:$C,MATCH("*Purchase Price*",Inputs!$B:$B,0))*Inputs!C93,0)} -> 0 | AV29: {=IF(AV$3=1,-INDEX(Inputs!$C:$C,MATCH("*Purchase Price*",Inputs!$B:$B,0))*Inputs!C93,0)} -> 0 | AW29: {=IF(AW$3=1,-INDEX(Inputs!$C:$C,MATCH("*Purchase Price*",Inputs!$B:$B,0))*Inputs!C93,0)} -> 0 | AX29: {=IF(AX$3=1,-INDEX(Inputs!$C:$C,MATCH("*Purchase Price*",Inputs!$B:$B,0))*Inputs!C93,0)} -> 0 | AY29: {=IF(AY$3=1,-INDEX(Inputs!$C:$C,MATCH("*Purchase Price*",Inputs!$B:$B,0))*Inputs!C93,0)} -> 0 | AZ29: {=IF(AZ$3=1,-INDEX(Inputs!$C:$C,MATCH("*Purchase Price*",Inputs!$B:$B,0))*Inputs!C93,0)} -> 0 | BA29: {=IF(BA$3=1,-INDEX(Inputs!$C:$C,MATCH("*Purchase Price*",Inputs!$B:$B,0))*Inputs!C93,0)} -> 0 | BB29: {=IF(BB$3=1,-INDEX(Inputs!$C:$C,MATCH("*Purchase Price*",Inputs!$B:$B,0))*Inputs!C93,0)} -> 0 | BC29: {=IF(BC$3=1,-INDEX(Inputs!$C:$C,MATCH("*Purchase Price*",Inputs!$B:$B,0))*Inputs!C93,0)} -> 0 | BD29: {=IF(BD$3=1,-INDEX(Inputs!$C:$C,MATCH("*Purchase Price*",Inputs!$B:$B,0))*Inputs!C93,0)} -> 0 | BE29: {=IF(BE$3=1,-INDEX(Inputs!$C:$C,MATCH("*Purchase Price*",Inputs!$B:$B,0))*Inputs!C93,0)} -> 0 | BF29: {=IF(BF$3=1,-INDEX(Inputs!$C:$C,MATCH("*Purchase Price*",Inputs!$B:$B,0))*Inputs!C93,0)} -> 0 | BG29: {=IF(BG$3=1,-INDEX(Inputs!$C:$C,MATCH("*Purchase Price*",Inputs!$B:$B,0))*Inputs!C93,0)} -> 0 | BH29: {=IF(BH$3=1,-INDEX(Inputs!$C:$C,MATCH("*Purchase Price*",Inputs!$B:$B,0))*Inputs!C93,0)} -> 0 | BI29: {=IF(BI$3=1,-INDEX(Inputs!$C:$C,MATCH("*Purchase Price*",Inputs!$B:$B,0))*Inputs!C93,0)} -> 0 | BJ29: {=IF(BJ$3=1,-INDEX(Inputs!$C:$C,MATCH("*Purchase Price*",Inputs!$B:$B,0))*Inputs!C93,0)} -> 0 | BK29: {=IF(BK$3=1,-INDEX(Inputs!$C:$C,MATCH("*Purchase Price*",Inputs!$B:$B,0))*Inputs!C93,0)} -> 0 | BL29: {=IF(BL$3=1,-INDEX(Inputs!$C:$C,MATCH("*Purchase Price*",Inputs!$B:$B,0))*Inputs!C93,0)} -> 0 | BM29: {=IF(BM$3=1,-INDEX(Inputs!$C:$C,MATCH("*Purchase Price*",Inputs!$B:$B,0))*Inputs!C93,0)} -> 0 | BN29: {=IF(BN$3=1,-INDEX(Inputs!$C:$C,MATCH("*Purchase Price*",Inputs!$B:$B,0))*Inputs!C93,0)} -> 0 | BO29: {=IF(BO$3=1,-INDEX(Inputs!$C:$C,MATCH("*Purchase Price*",Inputs!$B:$B,0))*Inputs!C93,0)} -> 0 | BP29: {=IF(BP$3=1,-INDEX(Inputs!$C:$C,MATCH("*Purchase Price*",Inputs!$B:$B,0))*Inputs!C93,0)} -> 0 | BQ29: {=IF(BQ$3=1,-INDEX(Inputs!$C:$C,MATCH("*Purchase Price*",Inputs!$B:$B,0))*Inputs!C93,0)} -> 0 | BR29: {=IF(BR$3=1,-INDEX(Inputs!$C:$C,MATCH("*Purchase Price*",Inputs!$B:$B,0))*Inputs!C93,0)} -> 0 | BS29: {=IF(BS$3=1,-INDEX(Inputs!$C:$C,MATCH("*Purchase Price*",Inputs!$B:$B,0))*Inputs!C93,0)} -> 0 | BT29: {=IF(BT$3=1,-INDEX(Inputs!$C:$C,MATCH("*Purchase Price*",Inputs!$B:$B,0))*Inputs!C93,0)} -> 0 | BU29: {=IF(BU$3=1,-INDEX(Inputs!$C:$C,MATCH("*Purchase Price*",Inputs!$B:$B,0))*Inputs!C93,0)} -> 0 | BV29: {=IF(BV$3=1,-INDEX(Inputs!$C:$C,MATCH("*Purchase Price*",Inputs!$B:$B,0))*Inputs!C93,0)} -> 0 | BW29: {=IF(BW$3=1,-INDEX(Inputs!$C:$C,MATCH("*Purchase Price*",Inputs!$B:$B,0))*Inputs!C93,0)} -> 0 | BX29: {=IF(BX$3=1,-INDEX(Inputs!$C:$C,MATCH("*Purchase Price*",Inputs!$B:$B,0))*Inputs!C93,0)} -> 0 | BY29: {=IF(BY$3=1,-INDEX(Inputs!$C:$C,MATCH("*Purchase Price*",Inputs!$B:$B,0))*Inputs!C93,0)} -> 0 | BZ29: {=IF(BZ$3=1,-INDEX(Inputs!$C:$C,MATCH("*Purchase Price*",Inputs!$B:$B,0))*Inputs!C93,0)} -> 0 | CA29: {=IF(CA$3=1,-INDEX(Inputs!$C:$C,MATCH("*Purchase Price*",Inputs!$B:$B,0))*Inputs!C93,0)} -> 0 | CB29: {=IF(CB$3=1,-INDEX(Inputs!$C:$C,MATCH("*Purchase Price*",Inputs!$B:$B,0))*Inputs!C93,0)} -> 0 | CC29: {=IF(CC$3=1,-INDEX(Inputs!$C:$C,MATCH("*Purchase Price*",Inputs!$B:$B,0))*Inputs!C93,0)} -> 0 | CD29: {=IF(CD$3=1,-INDEX(Inputs!$C:$C,MATCH("*Purchase Price*",Inputs!$B:$B,0))*Inputs!C93,0)} -> 0 | CE29: {=IF(CE$3=1,-INDEX(Inputs!$C:$C,MATCH("*Purchase Price*",Inputs!$B:$B,0))*Inputs!C93,0)} -> 0 | CF29: {=IF(CF$3=1,-INDEX(Inputs!$C:$C,MATCH("*Purchase Price*",Inputs!$B:$B,0))*Inputs!C93,0)} -> 0 | CG29: {=IF(CG$3=1,-INDEX(Inputs!$C:$C,MATCH("*Purchase Price*",Inputs!$B:$B,0))*Inputs!C93,0)} -> 0 | CH29: {=IF(CH$3=1,-INDEX(Inputs!$C:$C,MATCH("*Purchase Price*",Inputs!$B:$B,0))*Inputs!C93,0)} -> 0 | CI29: {=IF(CI$3=1,-INDEX(Inputs!$C:$C,MATCH("*Purchase Price*",Inputs!$B:$B,0))*Inputs!C93,0)} -> 0 | CJ29: {=IF(CJ$3=1,-INDEX(Inputs!$C:$C,MATCH("*Purchase Price*",Inputs!$B:$B,0))*Inputs!C93,0)} -> 0 | CK29: {=IF(CK$3=1,-INDEX(Inputs!$C:$C,MATCH("*Purchase Price*",Inputs!$B:$B,0))*Inputs!C93,0)} -> 0 | CL29: {=IF(CL$3=1,-INDEX(Inputs!$C:$C,MATCH("*Purchase Price*",Inputs!$B:$B,0))*Inputs!C93,0)} -> 0 | CM29: {=IF(CM$3=1,-INDEX(Inputs!$C:$C,MATCH("*Purchase Price*",Inputs!$B:$B,0))*Inputs!C93,0)} -> 0 | CN29: {=IF(CN$3=1,-INDEX(Inputs!$C:$C,MATCH("*Purchase Price*",Inputs!$B:$B,0))*Inputs!C93,0)} -> 0 | CO29: {=IF(CO$3=1,-INDEX(Inputs!$C:$C,MATCH("*Purchase Price*",Inputs!$B:$B,0))*Inputs!C93,0)} -> 0 | CP29: {=IF(CP$3=1,-INDEX(Inputs!$C:$C,MATCH("*Purchase Price*",Inputs!$B:$B,0))*Inputs!C93,0)} -> 0 | CQ29: {=IF(CQ$3=1,-INDEX(Inputs!$C:$C,MATCH("*Purchase Price*",Inputs!$B:$B,0))*Inputs!C93,0)} -> 0 | CR29: {=IF(CR$3=1,-INDEX(Inputs!$C:$C,MATCH("*Purchase Price*",Inputs!$B:$B,0))*Inputs!C93,0)} -> 0 | CS29: {=IF(CS$3=1,-INDEX(Inputs!$C:$C,MATCH("*Purchase Price*",Inputs!$B:$B,0))*Inputs!C93,0)} -> 0 | CT29: {=IF(CT$3=1,-INDEX(Inputs!$C:$C,MATCH("*Purchase Price*",Inputs!$B:$B,0))*Inputs!C93,0)} -> 0 | CU29: {=IF(CU$3=1,-INDEX(Inputs!$C:$C,MATCH("*Purchase Price*",Inputs!$B:$B,0))*Inputs!C93,0)} -> 0 | CV29: {=IF(CV$3=1,-INDEX(Inputs!$C:$C,MATCH("*Purchase Price*",Inputs!$B:$B,0))*Inputs!C93,0)} -> 0 | CW29: {=IF(CW$3=1,-INDEX(Inputs!$C:$C,MATCH("*Purchase Price*",Inputs!$B:$B,0))*Inputs!C93,0)} -> 0 | CX29: {=IF(CX$3=1,-INDEX(Inputs!$C:$C,MATCH("*Purchase Price*",Inputs!$B:$B,0))*Inputs!C93,0)} -> 0 | CY29: {=IF(CY$3=1,-INDEX(Inputs!$C:$C,MATCH("*Purchase Price*",Inputs!$B:$B,0))*Inputs!C93,0)} -> 0 | CZ29: {=IF(CZ$3=1,-INDEX(Inputs!$C:$C,MATCH("*Purchase Price*",Inputs!$B:$B,0))*Inputs!C93,0)} -> 0 | DA29: {=IF(DA$3=1,-INDEX(Inputs!$C:$C,MATCH("*Purchase Price*",Inputs!$B:$B,0))*Inputs!C93,0)} -> 0 | DB29: {=IF(DB$3=1,-INDEX(Inputs!$C:$C,MATCH("*Purchase Price*",Inputs!$B:$B,0))*Inputs!C93,0)} -> 0 | DC29: {=IF(DC$3=1,-INDEX(Inputs!$C:$C,MATCH("*Purchase Price*",Inputs!$B:$B,0))*Inputs!C93,0)} -> 0 | DD29: {=IF(DD$3=1,-INDEX(Inputs!$C:$C,MATCH("*Purchase Price*",Inputs!$B:$B,0))*Inputs!C93,0)} -> 0 | DE29: {=IF(DE$3=1,-INDEX(Inputs!$C:$C,MATCH("*Purchase Price*",Inputs!$B:$B,0))*Inputs!C93,0)} -> 0 | DF29: {=IF(DF$3=1,-INDEX(Inputs!$C:$C,MATCH("*Purchase Price*",Inputs!$B:$B,0))*Inputs!C93,0)} -> 0 | DG29: {=IF(DG$3=1,-INDEX(Inputs!$C:$C,MATCH("*Purchase Price*",Inputs!$B:$B,0))*Inputs!C93,0)} -> 0 | DH29: {=IF(DH$3=1,-INDEX(Inputs!$C:$C,MATCH("*Purchase Price*",Inputs!$B:$B,0))*Inputs!C93,0)} -> 0 | DI29: {=IF(DI$3=1,-INDEX(Inputs!$C:$C,MATCH("*Purchase Price*",Inputs!$B:$B,0))*Inputs!C93,0)} -> 0 | DJ29: {=IF(DJ$3=1,-INDEX(Inputs!$C:$C,MATCH("*Purchase Price*",Inputs!$B:$B,0))*Inputs!C93,0)} -> 0 | DK29: {=IF(DK$3=1,-INDEX(Inputs!$C:$C,MATCH("*Purchase Price*",Inputs!$B:$B,0))*Inputs!C93,0)} -> 0 | DL29: {=IF(DL$3=1,-INDEX(Inputs!$C:$C,MATCH("*Purchase Price*",Inputs!$B:$B,0))*Inputs!C93,0)} -> 0 | DM29: {=IF(DM$3=1,-INDEX(Inputs!$C:$C,MATCH("*Purchase Price*",Inputs!$B:$B,0))*Inputs!C93,0)} -> 0 | DN29: {=IF(DN$3=1,-INDEX(Inputs!$C:$C,MATCH("*Purchase Price*",Inputs!$B:$B,0))*Inputs!C93,0)} -> 0 | DO29: {=IF(DO$3=1,-INDEX(Inputs!$C:$C,MATCH("*Purchase Price*",Inputs!$B:$B,0))*Inputs!C93,0)} -> 0 | DP29: {=IF(DP$3=1,-INDEX(Inputs!$C:$C,MATCH("*Purchase Price*",Inputs!$B:$B,0))*Inputs!C93,0)} -> 0 | DQ29: {=IF(DQ$3=1,-INDEX(Inputs!$C:$C,MATCH("*Purchase Price*",Inputs!$B:$B,0))*Inputs!C93,0)} -> 0 | DR29: {=IF(DR$3=1,-INDEX(Inputs!$C:$C,MATCH("*Purchase Price*",Inputs!$B:$B,0))*Inputs!C93,0)} -> 0 | DS29: {=IF(DS$3=1,-INDEX(Inputs!$C:$C,MATCH("*Purchase Price*",Inputs!$B:$B,0))*Inputs!C93,0)} -> 0
B30: Due Diligence Costs | C30: {=IF(C$3=1,-INDEX(Inputs!$D:$D,MATCH("*Due Diligence Costs*",Inputs!$B:$B,0)),0)} -> 0 | D30: 0 | E30: 0 | F30: 0 | G30: 0 | H30: 0 | I30: 0 | J30: 0 | K30: 0 | L30: 0 | M30: 0 | N30: 0 | O30: 0 | P30: 0 | Q30: 0 | R30: 0 | S30: 0 | T30: 0 | U30: 0 | V30: 0 | W30: 0 | X30: 0 | Y30: 0 | Z30: 0 | AA30: 0 | AB30: 0 | AC30: 0 | AD30: 0 | AE30: 0 | AF30: 0 | AG30: 0 | AH30: 0 | AI30: 0 | AJ30: 0 | AK30: 0 | AL30: 0 | AM30: 0 | AN30: 0 | AO30: 0 | AP30: 0 | AQ30: 0 | AR30: 0 | AS30: 0 | AT30: 0 | AU30: 0 | AV30: 0 | AW30: 0 | AX30: 0 | AY30: 0 | AZ30: 0 | BA30: 0 | BB30: 0 | BC30: 0 | BD30: 0 | BE30: 0 | BF30: 0 | BG30: 0 | BH30: 0 | BI30: 0 | BJ30: 0 | BK30: 0 | BL30: 0 | BM30: 0 | BN30: 0 | BO30: 0 | BP30: 0 | BQ30: 0 | BR30: 0 | BS30: 0 | BT30: 0 | BU30: 0 | BV30: 0 | BW30: 0 | BX30: 0 | BY30: 0 | BZ30: 0 | CA30: 0 | CB30: 0 | CC30: 0 | CD30: 0 | CE30: 0 | CF30: 0 | CG30: 0 | CH30: 0 | CI30: 0 | CJ30: 0 | CK30: 0 | CL30: 0 | CM30: 0 | CN30: 0 | CO30: 0 | CP30: 0 | CQ30: 0 | CR30: 0 | CS30: 0 | CT30: 0 | CU30: 0 | CV30: 0 | CW30: 0 | CX30: 0 | CY30: 0 | CZ30: 0 | DA30: 0 | DB30: 0 | DC30: 0 | DD30: 0 | DE30: 0 | DF30: 0 | DG30: 0 | DH30: 0 | DI30: 0 | DJ30: 0 | DK30: 0 | DL30: 0 | DM30: 0 | DN30: 0 | DO30: 0 | DP30: 0 | DQ30: 0 | DR30: 0 | DS30: 0
B31: Loan Origination Costs | C31: {=IF(C$3=1,-INDEX(Inputs!$D:$D,MATCH("*Loan Origination Costs*",Inputs!$B:$B,0)),0)} -> 0 | D31: 0 | E31: 0 | F31: 0 | G31: 0 | H31: 0 | I31: 0 | J31: 0 | K31: 0 | L31: 0 | M31: 0 | N31: 0 | O31: 0 | P31: 0 | Q31: 0 | R31: 0 | S31: 0 | T31: 0 | U31: 0 | V31: 0 | W31: 0 | X31: 0 | Y31: 0 | Z31: 0 | AA31: 0 | AB31: 0 | AC31: 0 | AD31: 0 | AE31: 0 | AF31: 0 | AG31: 0 | AH31: 0 | AI31: 0 | AJ31: 0 | AK31: 0 | AL31: 0 | AM31: 0 | AN31: 0 | AO31: 0 | AP31: 0 | AQ31: 0 | AR31: 0 | AS31: 0 | AT31: 0 | AU31: 0 | AV31: 0 | AW31: 0 | AX31: 0 | AY31: 0 | AZ31: 0 | BA31: 0 | BB31: 0 | BC31: 0 | BD31: 0 | BE31: 0 | BF31: 0 | BG31: 0 | BH31: 0 | BI31: 0 | BJ31: 0 | BK31: 0 | BL31: 0 | BM31: 0 | BN31: 0 | BO31: 0 | BP31: 0 | BQ31: 0 | BR31: 0 | BS31: 0 | BT31: 0 | BU31: 0 | BV31: 0 | BW31: 0 | BX31: 0 | BY31: 0 | BZ31: 0 | CA31: 0 | CB31: 0 | CC31: 0 | CD31: 0 | CE31: 0 | CF31: 0 | CG31: 0 | CH31: 0 | CI31: 0 | CJ31: 0 | CK31: 0 | CL31: 0 | CM31: 0 | CN31: 0 | CO31: 0 | CP31: 0 | CQ31: 0 | CR31: 0 | CS31: 0 | CT31: 0 | CU31: 0 | CV31: 0 | CW31: 0 | CX31: 0 | CY31: 0 | CZ31: 0 | DA31: 0 | DB31: 0 | DC31: 0 | DD31: 0 | DE31: 0 | DF31: 0 | DG31: 0 | DH31: 0 | DI31: 0 | DJ31: 0 | DK31: 0 | DL31: 0 | DM31: 0 | DN31: 0 | DO31: 0 | DP31: 0 | DQ31: 0 | DR31: 0 | DS31: 0
B32: TOTAL ACQUISITION COSTS | C32: =SUM(C26:C31) -> -5000 | D32: =SUM(D26:D31) -> 0 | E32: =SUM(E26:E31) -> 0 | F32: =SUM(F26:F31) -> 0 | G32: =SUM(G26:G31) -> 0 | H32: =SUM(H26:H31) -> 0 | I32: =SUM(I26:I31) -> 0 | J32: =SUM(J26:J31) -> 0 | ... DS32: =SUM(DS26:DS31) -> 0
B34: DISPOSITION / EXIT
